Workbook

Sheet 목차
B2: 고객센터 서포팅 AI 챗봇(RAG) REST API 명세서
B4: ="작성일: "&TEXT(TODAY(),"yyyy-mm-dd")
B5: ="총 API 개수: "&COUNTIF('전체API목록'!$A:$A,">0")&"개"
B6: ="버전: v0.2 ("&TEXT(TODAY(),"yyyy-mm-dd")&")"
B8: 우선순위 | C8: 카테고리 | D8: API 개수 | E8: 개발 단계
B9: 1 | C9: 인증 및 세션 | D9: =COUNTIF('전체API목록'!$B:$B,C9) | E9: Phase 1 - 필수
B10: 2 | C10: 메시지 대화 | D10: =COUNTIF('전체API목록'!$B:$B,C10) | E10: Phase 1 - 필수
B11: 3 | C11: 스트리밍 SSE | D11: =COUNTIF('전체API목록'!$B:$B,C11) | E11: Phase 1 - 필수
B12: 4 | C12: 첨부 파일 | D12: =COUNTIF('전체API목록'!$B:$B,C12) | E12: Phase 2 - 핵심
B13: 5 | C13: RAG 검색 응답 | D13: =COUNTIF('전체API목록'!$B:$B,C13) | E13: Phase 2 - 핵심
B14: 6 | C14: 지식베이스 관리 | D14: =COUNTIF('전체API목록'!$B:$B,C14) | E14: Phase 2 - 핵심
B15: 7 | C15: 템플릿 정책 관리 | D15: =COUNTIF('전체API목록'!$B:$B,C15) | E15: Phase 3 - 중요
B16: 8 | C16: LLM 모델 시크릿 관리 | D16: =COUNTIF('전체API목록'!$B:$B,C16) | E16: Phase 3 - 중요
B17: 9 | C17: Tool MCP 연동 | D17: =COUNTIF('전체API목록'!$B:$B,C17) | E17: Phase 5 - 고도화
B18: 10 | C18: 운영 관측 통합 | D18: =COUNTIF('전체API목록'!$B:$B,C18) | E18: Phase 4 - 관리
B19: 11 | C19: 공통 규약 | D19: =COUNTIF('전체API목록'!$B:$B,C19) | E19: Phase 4 - 관리

Sheet 전체API목록
A1: 번호 | B1: 카테고리 | C1: 프로그램ID | D1: API명 | E1: Method | F1: Endpoint | G1: 설명 | H1: Request | I1: Response | J1: 권한 | K1: 비고
A2: =IF(B2="","",ROW()-1) | B2: 인증 및 세션 | C2: API-AUTH-LOGIN | D2: 로그인 토큰 발급 | E2: POST | F2: /v1/auth/login | G2: 로그인 토큰 발급 기능 제공 | H2: Headers: X-Trace-Id: <uuid>, X-Tenant-Key: <tenant_key>, Idempotency-Key: <uuid> Path Params: - Query Params: - Body(JSON): {"channel_id":"web","customer_token":"cust_xxx","client_nonce":"nonce_1"} Validation/Rules: 길이/형식 검증, PII 마스킹, top_k/timeout/rbac 정책 검증 | I2: 201: {"result":"accepted","id":"obj_1"} 4xx/5xx: {"error_code":"SYS-003-XXX","message":"...","trace_id":"...","details":[]} Notes: 민감 필드 제거, trace_id/session_id/message_id(해당 시) 반환 | J2: PUBLIC | K2: ReqID: SEC-001, UI-008 보안/PII/키관리: JWT+RBAC, PII 마스킹, 시크릿은 key_ref만 사용 멱등성: POST/PUT/PATCH는 Idempotency-Key 적용, GET은 N/A 레이트리밋: 429 + Retry-After + X-RateLimit-Limit/Remaining/Reset 에러/로그: SYS-003 error_code, trace_id 필수, metrics=latency_ms,error_rate 공통규약 적용: SEC-001, SEC-002, SEC-003, SYS-003, SYS-004, OPS-001
A3: =IF(B3="","",ROW()-1) | B3: 인증 및 세션 | C3: API-AUTH-REFRESH | D3: Access Token 재발급 | E3: POST | F3: /v1/auth/refresh | G3: Access Token 재발급 기능 제공 | H3: Headers: X-Trace-Id: <uuid>, X-Tenant-Key: <tenant_key>, Idempotency-Key: <uuid> Path Params: - Query Params: - Body(JSON): {"channel_id":"web","customer_token":"cust_xxx","client_nonce":"nonce_1"} Validation/Rules: 길이/형식 검증, PII 마스킹, top_k/timeout/rbac 정책 검증 | I3: 201: {"result":"accepted","id":"obj_1"} 4xx/5xx: {"error_code":"SYS-003-XXX","message":"...","trace_id":"...","details":[]} Notes: 민감 필드 제거, trace_id/session_id/message_id(해당 시) 반환 | J3: PUBLIC | K3: ReqID: SEC-001, UI-008 보안/PII/키관리: JWT+RBAC, PII 마스킹, 시크릿은 key_ref만 사용 멱등성: POST/PUT/PATCH는 Idempotency-Key 적용, GET은 N/A 레이트리밋: 429 + Retry-After + X-RateLimit-Limit/Remaining/Reset 에러/로그: SYS-003 error_code, trace_id 필수, metrics=latency_ms,error_rate 공통규약 적용: SEC-001, SEC-002, SEC-003, SYS-003, SYS-004, OPS-001
A4: =IF(B4="","",ROW()-1) | B4: 인증 및 세션 | C4: API-AUTH-LOGOUT | D4: 로그아웃 | E4: POST | F4: /v1/auth/logout | G4: 로그아웃 기능 제공 | H4: Headers: Authorization: Bearer <access_token>, X-Trace-Id: <uuid>, X-Tenant-Key: <tenant_key>, Idempotency-Key: <uuid> Path Params: - Query Params: - Body(JSON): {"channel_id":"web","customer_token":"cust_xxx","client_nonce":"nonce_1"} Validation/Rules: 길이/형식 검증, PII 마스킹, top_k/timeout/rbac 정책 검증 | I4: 201: {"result":"accepted","id":"obj_1"} 4xx/5xx: {"error_code":"SYS-003-XXX","message":"...","trace_id":"...","details":[]} Notes: 민감 필드 제거, trace_id/session_id/message_id(해당 시) 반환 | J4: CUSTOMER | K4: ReqID: SEC-001, OPS-001 보안/PII/키관리: JWT+RBAC, PII 마스킹, 시크릿은 key_ref만 사용 멱등성: POST/PUT/PATCH는 Idempotency-Key 적용, GET은 N/A 레이트리밋: 429 + Retry-After + X-RateLimit-Limit/Remaining/Reset 에러/로그: SYS-003 error_code, trace_id 필수, metrics=latency_ms,error_rate 공통규약 적용: SEC-001, SEC-002, SEC-003, SYS-003, SYS-004, OPS-001
A5: =IF(B5="","",ROW()-1) | B5: 인증 및 세션 | C5: API-SESSION-CREATE | D5: 세션 생성 | E5: POST | F5: /v1/sessions | G5: 세션 생성 기능 제공 | H5: Headers: Authorization: Bearer <access_token>, X-Trace-Id: <uuid>, X-Tenant-Key: <tenant_key>, Idempotency-Key: <uuid> Path Params: - Query Params: - Body(JSON): {"session_id":"ses_1","reason":"user_request"} Validation/Rules: 길이/형식 검증, PII 마스킹, top_k/timeout/rbac 정책 검증 | I5: 201: {"result":"accepted","id":"obj_1"} 4xx/5xx: {"error_code":"SYS-003-XXX","message":"...","trace_id":"...","details":[]} Notes: 민감 필드 제거, trace_id/session_id/message_id(해당 시) 반환 | J5: CUSTOMER | K5: ReqID: SYS-001, API-002, UI-001 보안/PII/키관리: JWT+RBAC, PII 마스킹, 시크릿은 key_ref만 사용 멱등성: POST/PUT/PATCH는 Idempotency-Key 적용, GET은 N/A 레이트리밋: 429 + Retry-After + X-RateLimit-Limit/Remaining/Reset 에러/로그: SYS-003 error_code, trace_id 필수, metrics=latency_ms,error_rate 공통규약 적용: SEC-001, SEC-002, SEC-003, SYS-003, SYS-004, OPS-001
A6: =IF(B6="","",ROW()-1) | B6: 인증 및 세션 | C6: API-SESSION-GET | D6: 세션 조회 | E6: GET | F6: /v1/sessions/{session_id} | G6: 세션 조회 기능 제공 | H6: Headers: Authorization: Bearer <access_token>, X-Trace-Id: <uuid>, X-Tenant-Key: <tenant_key> Path Params: session_id: string Query Params: cursor(optional), limit(optional) Body(JSON): - Validation/Rules: 길이/형식 검증, PII 마스킹, top_k/timeout/rbac 정책 검증 | I6: 200: {"result":"ok","data":{...}} 4xx/5xx: {"error_code":"SYS-003-XXX","message":"...","trace_id":"...","details":[]} Notes: 민감 필드 제거, trace_id/session_id/message_id(해당 시) 반환 | J6: CUSTOMER | K6: ReqID: SYS-001, API-002, UI-001 보안/PII/키관리: JWT+RBAC, PII 마스킹, 시크릿은 key_ref만 사용 멱등성: POST/PUT/PATCH는 Idempotency-Key 적용, GET은 N/A 레이트리밋: 429 + Retry-After + X-RateLimit-Limit/Remaining/Reset 에러/로그: SYS-003 error_code, trace_id 필수, metrics=latency_ms,error_rate 공통규약 적용: SEC-001, SEC-002, SEC-003, SYS-003, SYS-004, OPS-001
A7: =IF(B7="","",ROW()-1) | B7: 인증 및 세션 | C7: API-SESSION-CLOSE | D7: 세션 종료 | E7: POST | F7: /v1/sessions/{session_id}/close | G7: 세션 종료 기능 제공 | H7: Headers: Authorization: Bearer <access_token>, X-Trace-Id: <uuid>, X-Tenant-Key: <tenant_key>, Idempotency-Key: <uuid> Path Params: session_id: string Query Params: - Body(JSON): {"session_id":"ses_1","reason":"user_request"} Validation/Rules: 길이/형식 검증, PII 마스킹, top_k/timeout/rbac 정책 검증 | I7: 201: {"result":"accepted","id":"obj_1"} 4xx/5xx: {"error_code":"SYS-003-XXX","message":"...","trace_id":"...","details":[]} Notes: 민감 필드 제거, trace_id/session_id/message_id(해당 시) 반환 | J7: CUSTOMER | K7: ReqID: API-002, OPS-001 보안/PII/키관리: JWT+RBAC, PII 마스킹, 시크릿은 key_ref만 사용 멱등성: POST/PUT/PATCH는 Idempotency-Key 적용, GET은 N/A 레이트리밋: 429 + Retry-After + X-RateLimit-Limit/Remaining/Reset 에러/로그: SYS-003 error_code, trace_id 필수, metrics=latency_ms,error_rate 공통규약 적용: SEC-001, SEC-002, SEC-003, SYS-003, SYS-004, OPS-001
A8: =IF(B8="","",ROW()-1) | B8: 인증 및 세션 | C8: API-SESSION-BOOTSTRAP | D8: 채팅 부트스트랩 | E8: GET | F8: /v1/chat/bootstrap | G8: 채팅 부트스트랩 기능 제공 | H8: Headers: Authorization: Bearer <access_token>, X-Trace-Id: <uuid>, X-Tenant-Key: <tenant_key> Path Params: - Query Params: channel_id, locale, host, tenant_key Body(JSON): - Validation/Rules: 길이/형식 검증, PII 마스킹, top_k/timeout/rbac 정책 검증 | I8: 200: {"result":"ok","data":{...}} 4xx/5xx: {"error_code":"SYS-003-XXX","message":"...","trace_id":"...","details":[]} Notes: 민감 필드 제거, trace_id/session_id/message_id(해당 시) 반환 | J8: CUSTOMER | K8: ReqID: API-001, SYS-001, SYS-002, UI-001 보안/PII/키관리: JWT+RBAC, PII 마스킹, 시크릿은 key_ref만 사용 멱등성: POST/PUT/PATCH는 Idempotency-Key 적용, GET은 N/A 레이트리밋: 429 + Retry-After + X-RateLimit-Limit/Remaining/Reset 에러/로그: SYS-003 error_code, trace_id 필수, metrics=latency_ms,error_rate 공통규약 적용: SEC-001, SEC-002, SEC-003, SYS-003, SYS-004, OPS-001
A9: =IF(B9="","",ROW()-1) | B9: 메시지 대화 | C9: API-MESSAGE-POST | D9: 질문 전송 | E9: POST | F9: /v1/sessions/{session_id}/messages | G9: 질문 전송 기능 제공 | H9: Headers: Authorization: Bearer <access_token>, X-Trace-Id: <uuid>, X-Tenant-Key: <tenant_key>, Idempotency-Key: <uuid> Path Params: session_id: string Query Params: - Body(JSON): {"text":"문의 내용","attachments":["att_1"],"client_nonce":"msg_nonce_1"} Validation/Rules: 길이/형식 검증, PII 마스킹, top_k/timeout/rbac 정책 검증 Validation/Rules+: enforce input_token_max, output_token_max, tool_call_max, top_k_max, session_budget_max; exceed => 429/403 + cooldown. | I9: 202: {"result":"accepted","id":"obj_1"} 4xx/5xx: {"error_code":"SYS-003-XXX","message":"...","trace_id":"...","details":[]} Notes: 민감 필드 제거, trace_id/session_id/message_id(해당 시) 반환 Policy: schema/citation/evidence failure => fail-closed safe_response or error code (no free-text fallback). | J9: AGENT | K9: ReqID: API-003, UI-002, KB-001 보안/PII/키관리: JWT+RBAC, PII 마스킹, 시크릿은 key_ref만 사용 멱등성: POST/PUT/PATCH는 Idempotency-Key 적용, GET은 N/A 레이트리밋: 429 + Retry-After + X-RateLimit-Limit/Remaining/Reset 에러/로그: SYS-003 error_code, trace_id 필수, metrics=latency_ms,error_rate 공통규약 적용: SEC-001, SEC-002, SEC-003, SYS-003, SYS-004, OPS-001 MVP Role: AGENT (agent-console-first). Customer channel exposure must be policy-gated. CommonRule+: COM-BUDGET-GUARD-RULE, COM-ANSWER-CONTRACT-RULE
A10: =IF(B10="","",ROW()-1) | B10: 메시지 대화 | C10: API-MESSAGE-RETRY | D10: 질문 재전송 | E10: POST | F10: /v1/sessions/{session_id}/messages/{message_id}/retry | G10: 질문 재전송 기능 제공 | H10: Headers: Authorization: Bearer <access_token>, X-Trace-Id: <uuid>, X-Tenant-Key: <tenant_key>, Idempotency-Key: <uuid> Path Params: session_id: string, message_id: string Query Params: - Body(JSON): {"text":"문의 내용","attachments":["att_1"],"client_nonce":"msg_nonce_1"} Validation/Rules: 길이/형식 검증, PII 마스킹, top_k/timeout/rbac 정책 검증 Validation/Rules+: enforce input_token_max, output_token_max, tool_call_max, top_k_max, session_budget_max; exceed => 429/403 + cooldown. | I10: 202: {"result":"accepted","id":"obj_1"} 4xx/5xx: {"error_code":"SYS-003-XXX","message":"...","trace_id":"...","details":[]} Notes: 민감 필드 제거, trace_id/session_id/message_id(해당 시) 반환 Policy: schema/citation/evidence failure => fail-closed safe_response or error code (no free-text fallback). | J10: AGENT | K10: ReqID: API-003, UI-002 보안/PII/키관리: JWT+RBAC, PII 마스킹, 시크릿은 key_ref만 사용 멱등성: POST/PUT/PATCH는 Idempotency-Key 적용, GET은 N/A 레이트리밋: 429 + Retry-After + X-RateLimit-Limit/Remaining/Reset 에러/로그: SYS-003 error_code, trace_id 필수, metrics=latency_ms,error_rate 공통규약 적용: SEC-001, SEC-002, SEC-003, SYS-003, SYS-004, OPS-001 MVP Role: AGENT (agent-console-first). Customer channel exposure must be policy-gated. CommonRule+: COM-BUDGET-GUARD-RULE, COM-ANSWER-CONTRACT-RULE
A11: =IF(B11="","",ROW()-1) | B11: 메시지 대화 | C11: API-MESSAGE-LIST | D11: 메시지 목록 | E11: GET | F11: /v1/sessions/{session_id}/messages | G11: 메시지 목록 기능 제공 | H11: Headers: Authorization: Bearer <access_token>, X-Trace-Id: <uuid>, X-Tenant-Key: <tenant_key> Path Params: session_id: string Query Params: page, size, keyword(optional), from(optional), to(optional) Body(JSON): - Validation/Rules: 길이/형식 검증, PII 마스킹, top_k/timeout/rbac 정책 검증 | I11: 200: {"items":[...],"total":100} 4xx/5xx: {"error_code":"SYS-003-XXX","message":"...","trace_id":"...","details":[]} Notes: 민감 필드 제거, trace_id/session_id/message_id(해당 시) 반환 | J11: AGENT | K11: ReqID: API-001, UI-001 보안/PII/키관리: JWT+RBAC, PII 마스킹, 시크릿은 key_ref만 사용 멱등성: POST/PUT/PATCH는 Idempotency-Key 적용, GET은 N/A 레이트리밋: 429 + Retry-After + X-RateLimit-Limit/Remaining/Reset 에러/로그: SYS-003 error_code, trace_id 필수, metrics=latency_ms,error_rate 공통규약 적용: SEC-001, SEC-002, SEC-003, SYS-003, SYS-004, OPS-001 MVP Role: AGENT (agent-console-first). Customer channel exposure must be policy-gated. CommonRule+: COM-BUDGET-GUARD-RULE, COM-ANSWER-CONTRACT-RULE
A12: =IF(B12="","",ROW()-1) | B12: 메시지 대화 | C12: API-QUICKREPLY-POST | D12: 퀵리플라이 전송 | E12: POST | F12: /v1/sessions/{session_id}/quick-replies/{quick_reply_id} | G12: 퀵리플라이 전송 기능 제공 | H12: Headers: Authorization: Bearer <access_token>, X-Trace-Id: <uuid>, X-Tenant-Key: <tenant_key>, Idempotency-Key: <uuid> Path Params: session_id: string, quick_reply_id: string Query Params: - Body(JSON): {"text":"문의 내용","attachments":["att_1"],"client_nonce":"msg_nonce_1"} Validation/Rules: 길이/형식 검증, PII 마스킹, top_k/timeout/rbac 정책 검증 Validation/Rules+: enforce input_token_max, output_token_max, tool_call_max, top_k_max, session_budget_max; exceed => 429/403 + cooldown. | I12: 201: {"result":"accepted","id":"obj_1"} 4xx/5xx: {"error_code":"SYS-003-XXX","message":"...","trace_id":"...","details":[]} Notes: 민감 필드 제거, trace_id/session_id/message_id(해당 시) 반환 Policy: schema/citation/evidence failure => fail-closed safe_response or error code (no free-text fallback). | J12: AGENT | K12: ReqID: API-003, UI-002 보안/PII/키관리: JWT+RBAC, PII 마스킹, 시크릿은 key_ref만 사용 멱등성: POST/PUT/PATCH는 Idempotency-Key 적용, GET은 N/A 레이트리밋: 429 + Retry-After + X-RateLimit-Limit/Remaining/Reset 에러/로그: SYS-003 error_code, trace_id 필수, metrics=latency_ms,error_rate 공통규약 적용: SEC-001, SEC-002, SEC-003, SYS-003, SYS-004, OPS-001 MVP Role: AGENT (agent-console-first). Customer channel exposure must be policy-gated. CommonRule+: COM-BUDGET-GUARD-RULE, COM-ANSWER-CONTRACT-RULE
A13: =IF(B13="","",ROW()-1) | B13: 메시지 대화 | C13: API-CSAT-POST | D13: CSAT 제출 | E13: POST | F13: /v1/sessions/{session_id}/csat | G13: CSAT 제출 기능 제공 | H13: Headers: Authorization: Bearer <access_token>, X-Trace-Id: <uuid>, X-Tenant-Key: <tenant_key>, Idempotency-Key: <uuid> Path Params: session_id: string Query Params: - Body(JSON): {"score":4,"resolved":true,"comment":"도움됨"} Validation/Rules: 길이/형식 검증, PII 마스킹, top_k/timeout/rbac 정책 검증 | I13: 201: {"result":"accepted","id":"obj_1"} 4xx/5xx: {"error_code":"SYS-003-XXX","message":"...","trace_id":"...","details":[]} Notes: 민감 필드 제거, trace_id/session_id/message_id(해당 시) 반환 | J13: CUSTOMER | K13: ReqID: API-005, UI-007, INT-003 보안/PII/키관리: JWT+RBAC, PII 마스킹, 시크릿은 key_ref만 사용 멱등성: POST/PUT/PATCH는 Idempotency-Key 적용, GET은 N/A 레이트리밋: 429 + Retry-After + X-RateLimit-Limit/Remaining/Reset 에러/로그: SYS-003 error_code, trace_id 필수, metrics=latency_ms,error_rate 공통규약 적용: SEC-001, SEC-002, SEC-003, SYS-003, SYS-004, OPS-001
... A74: =IF(B74="","",ROW()-1) | B74: 운영 관측 통합 | C74: OPS-ROLLBACK-TRIGGER | D74: Policy/Prompt/KB Rollback Trigger | E74: POST | F74: /v1/ops/rollbacks | G74: Immediate action API to trigger rollback for policy/prompt/KB versions. | H74: Headers: Authorization: Bearer <access_token>, X-Trace-Id, X-Tenant-Key, Idempotency-Key Path Params: - Query Params: - Body(JSON): {"target_type":"policy|prompt|kb","target_id":"...","to_version":"...","reason":"incident_mitigation"} Validation/Rules: rollback target must be approved version; runbook step id required. | I74: 202: {"result":"accepted","job_id":"rbk_1","trace_id":"..."} 409: {"error_code":"OPS-003-INVALID_TARGET","message":"rollback target invalid","trace_id":"..."} 4xx/5xx: {"error_code":"SYS-003-XXX","message":"...","trace_id":"..."} | J74: OPS | K74: ReqID: OPS-003, ADM-003, KB-003 ImmediateAction: policy/prompt/kb rollback CommonRule: COM-TRACE-LOG-RULE, COM-IDEMPOTENCY-RULE
A75: =IF(B75="","",ROW()-1)
A76: =IF(B76="","",ROW()-1)
A77: =IF(B77="","",ROW()-1)
A78: =IF(B78="","",ROW()-1)
A79: =IF(B79="","",ROW()-1)
A80: =IF(B80="","",ROW()-1)
A81: =IF(B81="","",ROW()-1)
A82: =IF(B82="","",ROW()-1)
A83: =IF(B83="","",ROW()-1)
A84: =IF(B84="","",ROW()-1)
A85: =IF(B85="","",ROW()-1)
A86: =IF(B86="","",ROW()-1)
... A1200: =IF(B1200="","",ROW()-1)

Sheet 프로그램ID목록
A1: 번호 | B1: 프로그램ID | C1: API명 | D1: Method | E1: Endpoint | F1: 카테고리 | G1: 권한 | H1: 비고
A2: =IF(B2="","",ROW()-1) | B2: =IFERROR(INDEX(SORT(UNIQUE(FILTER('전체API목록'!$C$2:$C$1200,'전체API목록'!$C$2:$C$1200<>""))),ROW()-1),"") | C2: =IF(B2="","",IFERROR(XLOOKUP(B2,'전체API목록'!$C$2:$C$1200,'전체API목록'!$D$2:$D$1200,""),"")) | D2: =IF(B2="","",IFERROR(XLOOKUP(B2,'전체API목록'!$C$2:$C$1200,'전체API목록'!$E$2:$E$1200,""),"")) | E2: =IF(B2="","",IFERROR(XLOOKUP(B2,'전체API목록'!$C$2:$C$1200,'전체API목록'!$F$2:$F$1200,""),"")) | F2: =IF(B2="","",IFERROR(XLOOKUP(B2,'전체API목록'!$C$2:$C$1200,'전체API목록'!$B$2:$B$1200,""),"")) | G2: =IF(B2="","",IFERROR(XLOOKUP(B2,'전체API목록'!$C$2:$C$1200,'전체API목록'!$J$2:$J$1200,""),"")) | H2: =IF(B2="","",IFERROR(XLOOKUP(B2,'전체API목록'!$C$2:$C$1200,'전체API목록'!$K$2:$K$1200,""),""))
A3: =IF(B3="","",ROW()-1) | B3: =IFERROR(INDEX(SORT(UNIQUE(FILTER('전체API목록'!$C$2:$C$1200,'전체API목록'!$C$2:$C$1200<>""))),ROW()-1),"") | C3: =IF(B3="","",IFERROR(XLOOKUP(B3,'전체API목록'!$C$2:$C$1200,'전체API목록'!$D$2:$D$1200,""),"")) | D3: =IF(B3="","",IFERROR(XLOOKUP(B3,'전체API목록'!$C$2:$C$1200,'전체API목록'!$E$2:$E$1200,""),"")) | E3: =IF(B3="","",IFERROR(XLOOKUP(B3,'전체API목록'!$C$2:$C$1200,'전체API목록'!$F$2:$F$1200,""),"")) | F3: =IF(B3="","",IFERROR(XLOOKUP(B3,'전체API목록'!$C$2:$C$1200,'전체API목록'!$B$2:$B$1200,""),"")) | G3: =IF(B3="","",IFERROR(XLOOKUP(B3,'전체API목록'!$C$2:$C$1200,'전체API목록'!$J$2:$J$1200,""),"")) | H3: =IF(B3="","",IFERROR(XLOOKUP(B3,'전체API목록'!$C$2:$C$1200,'전체API목록'!$K$2:$K$1200,""),""))
A4: =IF(B4="","",ROW()-1) | B4: =IFERROR(INDEX(SORT(UNIQUE(FILTER('전체API목록'!$C$2:$C$1200,'전체API목록'!$C$2:$C$1200<>""))),ROW()-1),"") | C4: =IF(B4="","",IFERROR(XLOOKUP(B4,'전체API목록'!$C$2:$C$1200,'전체API목록'!$D$2:$D$1200,""),"")) | D4: =IF(B4="","",IFERROR(XLOOKUP(B4,'전체API목록'!$C$2:$C$1200,'전체API목록'!$E$2:$E$1200,""),"")) | E4: =IF(B4="","",IFERROR(XLOOKUP(B4,'전체API목록'!$C$2:$C$1200,'전체API목록'!$F$2:$F$1200,""),"")) | F4: =IF(B4="","",IFERROR(XLOOKUP(B4,'전체API목록'!$C$2:$C$1200,'전체API목록'!$B$2:$B$1200,""),"")) | G4: =IF(B4="","",IFERROR(XLOOKUP(B4,'전체API목록'!$C$2:$C$1200,'전체API목록'!$J$2:$J$1200,""),"")) | H4: =IF(B4="","",IFERROR(XLOOKUP(B4,'전체API목록'!$C$2:$C$1200,'전체API목록'!$K$2:$K$1200,""),""))
A5: =IF(B5="","",ROW()-1) | B5: =IFERROR(INDEX(SORT(UNIQUE(FILTER('전체API목록'!$C$2:$C$1200,'전체API목록'!$C$2:$C$1200<>""))),ROW()-1),"") | C5: =IF(B5="","",IFERROR(XLOOKUP(B5,'전체API목록'!$C$2:$C$1200,'전체API목록'!$D$2:$D$1200,""),"")) | D5: =IF(B5="","",IFERROR(XLOOKUP(B5,'전체API목록'!$C$2:$C$1200,'전체API목록'!$E$2:$E$1200,""),"")) | E5: =IF(B5="","",IFERROR(XLOOKUP(B5,'전체API목록'!$C$2:$C$1200,'전체API목록'!$F$2:$F$1200,""),"")) | F5: =IF(B5="","",IFERROR(XLOOKUP(B5,'전체API목록'!$C$2:$C$1200,'전체API목록'!$B$2:$B$1200,""),"")) | G5: =IF(B5="","",IFERROR(XLOOKUP(B5,'전체API목록'!$C$2:$C$1200,'전체API목록'!$J$2:$J$1200,""),"")) | H5: =IF(B5="","",IFERROR(XLOOKUP(B5,'전체API목록'!$C$2:$C$1200,'전체API목록'!$K$2:$K$1200,""),""))
A6: =IF(B6="","",ROW()-1) | B6: =IFERROR(INDEX(SORT(UNIQUE(FILTER('전체API목록'!$C$2:$C$1200,'전체API목록'!$C$2:$C$1200<>""))),ROW()-1),"") | C6: =IF(B6="","",IFERROR(XLOOKUP(B6,'전체API목록'!$C$2:$C$1200,'전체API목록'!$D$2:$D$1200,""),"")) | D6: =IF(B6="","",IFERROR(XLOOKUP(B6,'전체API목록'!$C$2:$C$1200,'전체API목록'!$E$2:$E$1200,""),"")) | E6: =IF(B6="","",IFERROR(XLOOKUP(B6,'전체API목록'!$C$2:$C$1200,'전체API목록'!$F$2:$F$1200,""),"")) | F6: =IF(B6="","",IFERROR(XLOOKUP(B6,'전체API목록'!$C$2:$C$1200,'전체API목록'!$B$2:$B$1200,""),"")) | G6: =IF(B6="","",IFERROR(XLOOKUP(B6,'전체API목록'!$C$2:$C$1200,'전체API목록'!$J$2:$J$1200,""),"")) | H6: =IF(B6="","",IFERROR(XLOOKUP(B6,'전체API목록'!$C$2:$C$1200,'전체API목록'!$K$2:$K$1200,""),""))
A7: =IF(B7="","",ROW()-1) | B7: =IFERROR(INDEX(SORT(UNIQUE(FILTER('전체API목록'!$C$2:$C$1200,'전체API목록'!$C$2:$C$1200<>""))),ROW()-1),"") | C7: =IF(B7="","",IFERROR(XLOOKUP(B7,'전체API목록'!$C$2:$C$1200,'전체API목록'!$D$2:$D$1200,""),"")) | D7: =IF(B7="","",IFERROR(XLOOKUP(B7,'전체API목록'!$C$2:$C$1200,'전체API목록'!$E$2:$E$1200,""),"")) | E7: =IF(B7="","",IFERROR(XLOOKUP(B7,'전체API목록'!$C$2:$C$1200,'전체API목록'!$F$2:$F$1200,""),"")) | F7: =IF(B7="","",IFERROR(XLOOKUP(B7,'전체API목록'!$C$2:$C$1200,'전체API목록'!$B$2:$B$1200,""),"")) | G7: =IF(B7="","",IFERROR(XLOOKUP(B7,'전체API목록'!$C$2:$C$1200,'전체API목록'!$J$2:$J$1200,""),"")) | H7: =IF(B7="","",IFERROR(XLOOKUP(B7,'전체API목록'!$C$2:$C$1200,'전체API목록'!$K$2:$K$1200,""),""))
A8: =IF(B8="","",ROW()-1) | B8: =IFERROR(INDEX(SORT(UNIQUE(FILTER('전체API목록'!$C$2:$C$1200,'전체API목록'!$C$2:$C$1200<>""))),ROW()-1),"") | C8: =IF(B8="","",IFERROR(XLOOKUP(B8,'전체API목록'!$C$2:$C$1200,'전체API목록'!$D$2:$D$1200,""),"")) | D8: =IF(B8="","",IFERROR(XLOOKUP(B8,'전체API목록'!$C$2:$C$1200,'전체API목록'!$E$2:$E$1200,""),"")) | E8: =IF(B8="","",IFERROR(XLOOKUP(B8,'전체API목록'!$C$2:$C$1200,'전체API목록'!$F$2:$F$1200,""),"")) | F8: =IF(B8="","",IFERROR(XLOOKUP(B8,'전체API목록'!$C$2:$C$1200,'전체API목록'!$B$2:$B$1200,""),"")) | G8: =IF(B8="","",IFERROR(XLOOKUP(B8,'전체API목록'!$C$2:$C$1200,'전체API목록'!$J$2:$J$1200,""),"")) | H8: =IF(B8="","",IFERROR(XLOOKUP(B8,'전체API목록'!$C$2:$C$1200,'전체API목록'!$K$2:$K$1200,""),""))
A9: =IF(B9="","",ROW()-1) | B9: =IFERROR(INDEX(SORT(UNIQUE(FILTER('전체API목록'!$C$2:$C$1200,'전체API목록'!$C$2:$C$1200<>""))),ROW()-1),"") | C9: =IF(B9="","",IFERROR(XLOOKUP(B9,'전체API목록'!$C$2:$C$1200,'전체API목록'!$D$2:$D$1200,""),"")) | D9: =IF(B9="","",IFERROR(XLOOKUP(B9,'전체API목록'!$C$2:$C$1200,'전체API목록'!$E$2:$E$1200,""),"")) | E9: =IF(B9="","",IFERROR(XLOOKUP(B9,'전체API목록'!$C$2:$C$1200,'전체API목록'!$F$2:$F$1200,""),"")) | F9: =IF(B9="","",IFERROR(XLOOKUP(B9,'전체API목록'!$C$2:$C$1200,'전체API목록'!$B$2:$B$1200,""),"")) | G9: =IF(B9="","",IFERROR(XLOOKUP(B9,'전체API목록'!$C$2:$C$1200,'전체API목록'!$J$2:$J$1200,""),"")) | H9: =IF(B9="","",IFERROR(XLOOKUP(B9,'전체API목록'!$C$2:$C$1200,'전체API목록'!$K$2:$K$1200,""),""))
A10: =IF(B10="","",ROW()-1) | B10: =IFERROR(INDEX(SORT(UNIQUE(FILTER('전체API목록'!$C$2:$C$1200,'전체API목록'!$C$2:$C$1200<>""))),ROW()-1),"") | C10: =IF(B10="","",IFERROR(XLOOKUP(B10,'전체API목록'!$C$2:$C$1200,'전체API목록'!$D$2:$D$1200,""),"")) | D10: =IF(B10="","",IFERROR(XLOOKUP(B10,'전체API목록'!$C$2:$C$1200,'전체API목록'!$E$2:$E$1200,""),"")) | E10: =IF(B10="","",IFERROR(XLOOKUP(B10,'전체API목록'!$C$2:$C$1200,'전체API목록'!$F$2:$F$1200,""),"")) | F10: =IF(B10="","",IFERROR(XLOOKUP(B10,'전체API목록'!$C$2:$C$1200,'전체API목록'!$B$2:$B$1200,""),"")) | G10: =IF(B10="","",IFERROR(XLOOKUP(B10,'전체API목록'!$C$2:$C$1200,'전체API목록'!$J$2:$J$1200,""),"")) | H10: =IF(B10="","",IFERROR(XLOOKUP(B10,'전체API목록'!$C$2:$C$1200,'전체API목록'!$K$2:$K$1200,""),""))
A11: =IF(B11="","",ROW()-1) | B11: =IFERROR(INDEX(SORT(UNIQUE(FILTER('전체API목록'!$C$2:$C$1200,'전체API목록'!$C$2:$C$1200<>""))),ROW()-1),"") | C11: =IF(B11="","",IFERROR(XLOOKUP(B11,'전체API목록'!$C$2:$C$1200,'전체API목록'!$D$2:$D$1200,""),"")) | D11: =IF(B11="","",IFERROR(XLOOKUP(B11,'전체API목록'!$C$2:$C$1200,'전체API목록'!$E$2:$E$1200,""),"")) | E11: =IF(B11="","",IFERROR(XLOOKUP(B11,'전체API목록'!$C$2:$C$1200,'전체API목록'!$F$2:$F$1200,""),"")) | F11: =IF(B11="","",IFERROR(XLOOKUP(B11,'전체API목록'!$C$2:$C$1200,'전체API목록'!$B$2:$B$1200,""),"")) | G11: =IF(B11="","",IFERROR(XLOOKUP(B11,'전체API목록'!$C$2:$C$1200,'전체API목록'!$J$2:$J$1200,""),"")) | H11: =IF(B11="","",IFERROR(XLOOKUP(B11,'전체API목록'!$C$2:$C$1200,'전체API목록'!$K$2:$K$1200,""),""))
A12: =IF(B12="","",ROW()-1) | B12: =IFERROR(INDEX(SORT(UNIQUE(FILTER('전체API목록'!$C$2:$C$1200,'전체API목록'!$C$2:$C$1200<>""))),ROW()-1),"") | C12: =IF(B12="","",IFERROR(XLOOKUP(B12,'전체API목록'!$C$2:$C$1200,'전체API목록'!$D$2:$D$1200,""),"")) | D12: =IF(B12="","",IFERROR(XLOOKUP(B12,'전체API목록'!$C$2:$C$1200,'전체API목록'!$E$2:$E$1200,""),"")) | E12: =IF(B12="","",IFERROR(XLOOKUP(B12,'전체API목록'!$C$2:$C$1200,'전체API목록'!$F$2:$F$1200,""),"")) | F12: =IF(B12="","",IFERROR(XLOOKUP(B12,'전체API목록'!$C$2:$C$1200,'전체API목록'!$B$2:$B$1200,""),"")) | G12: =IF(B12="","",IFERROR(XLOOKUP(B12,'전체API목록'!$C$2:$C$1200,'전체API목록'!$J$2:$J$1200,""),"")) | H12: =IF(B12="","",IFERROR(XLOOKUP(B12,'전체API목록'!$C$2:$C$1200,'전체API목록'!$K$2:$K$1200,""),""))
A13: =IF(B13="","",ROW()-1) | B13: =IFERROR(INDEX(SORT(UNIQUE(FILTER('전체API목록'!$C$2:$C$1200,'전체API목록'!$C$2:$C$1200<>""))),ROW()-1),"") | C13: =IF(B13="","",IFERROR(XLOOKUP(B13,'전체API목록'!$C$2:$C$1200,'전체API목록'!$D$2:$D$1200,""),"")) | D13: =IF(B13="","",IFERROR(XLOOKUP(B13,'전체API목록'!$C$2:$C$1200,'전체API목록'!$E$2:$E$1200,""),"")) | E13: =IF(B13="","",IFERROR(XLOOKUP(B13,'전체API목록'!$C$2:$C$1200,'전체API목록'!$F$2:$F$1200,""),"")) | F13: =IF(B13="","",IFERROR(XLOOKUP(B13,'전체API목록'!$C$2:$C$1200,'전체API목록'!$B$2:$B$1200,""),"")) | G13: =IF(B13="","",IFERROR(XLOOKUP(B13,'전체API목록'!$C$2:$C$1200,'전체API목록'!$J$2:$J$1200,""),"")) | H13: =IF(B13="","",IFERROR(XLOOKUP(B13,'전체API목록'!$C$2:$C$1200,'전체API목록'!$K$2:$K$1200,""),""))
... A1200: =IF(B1200="","",ROW()-1) | B1200: =IFERROR(INDEX(SORT(UNIQUE(FILTER('전체API목록'!$C$2:$C$1200,'전체API목록'!$C$2:$C$1200<>""))),ROW()-1),"") | C1200: =IF(B1200="","",IFERROR(XLOOKUP(B1200,'전체API목록'!$C$2:$C$1200,'전체API목록'!$D$2:$D$1200,""),"")) | D1200: =IF(B1200="","",IFERROR(XLOOKUP(B1200,'전체API목록'!$C$2:$C$1200,'전체API목록'!$E$2:$E$1200,""),"")) | E1200: =IF(B1200="","",IFERROR(XLOOKUP(B1200,'전체API목록'!$C$2:$C$1200,'전체API목록'!$F$2:$F$1200,""),"")) | F1200: =IF(B1200="","",IFERROR(XLOOKUP(B1200,'전체API목록'!$C$2:$C$1200,'전체API목록'!$B$2:$B$1200,""),"")) | G1200: =IF(B1200="","",IFERROR(XLOOKUP(B1200,'전체API목록'!$C$2:$C$1200,'전체API목록'!$J$2:$J$1200,""),"")) | H1200: =IF(B1200="","",IFERROR(XLOOKUP(B1200,'전체API목록'!$C$2:$C$1200,'전체API목록'!$K$2:$K$1200,""),""))

Sheet 인증 및 세션
A1: 인증 및 세션 API 명세
A2: 번호 | B2: 카테고리 | C2: 프로그램ID | D2: API명 | E2: Method | F2: Endpoint | G2: 설명 | H2: Request | I2: Response | J2: 권한 | K2: 비고
A3: =IFERROR(INDEX(FILTER('전체API목록'!$A$2:$K$1200,'전체API목록'!$B$2:$B$1200="인증 및 세션"),ROW()-2,COLUMN()),"") | B3: =IFERROR(INDEX(FILTER('전체API목록'!$A$2:$K$1200,'전체API목록'!$B$2:$B$1200="인증 및 세션"),ROW()-2,COLUMN()),"") | C3: =IFERROR(INDEX(FILTER('전체API목록'!$A$2:$K$1200,'전체API목록'!$B$2:$B$1200="인증 및 세션"),ROW()-2,COLUMN()),"") | D3: =IFERROR(INDEX(FILTER('전체API목록'!$A$2:$K$1200,'전체API목록'!$B$2:$B$1200="인증 및 세션"),ROW()-2,COLUMN()),"") | E3: =IFERROR(INDEX(FILTER('전체API목록'!$A$2:$K$1200,'전체API목록'!$B$2:$B$1200="인증 및 세션"),ROW()-2,COLUMN()),"") | F3: =IFERROR(INDEX(FILTER('전체API목록'!$A$2:$K$1200,'전체API목록'!$B$2:$B$1200="인증 및 세션"),ROW()-2,COLUMN()),"") | G3: =IFERROR(INDEX(FILTER('전체API목록'!$A$2:$K$1200,'전체API목록'!$B$2:$B$1200="인증 및 세션"),ROW()-2,COLUMN()),"") | H3: =IFERROR(INDEX(FILTER('전체API목록'!$A$2:$K$1200,'전체API목록'!$B$2:$B$1200="인증 및 세션"),ROW()-2,COLUMN()),"") | ... K3: =IFERROR(INDEX(FILTER('전체API목록'!$A$2:$K$1200,'전체API목록'!$B$2:$B$1200="인증 및 세션"),ROW()-2,COLUMN()),"")
A4: =IFERROR(INDEX(FILTER('전체API목록'!$A$2:$K$1200,'전체API목록'!$B$2:$B$1200="인증 및 세션"),ROW()-2,COLUMN()),"") | B4: =IFERROR(INDEX(FILTER('전체API목록'!$A$2:$K$1200,'전체API목록'!$B$2:$B$1200="인증 및 세션"),ROW()-2,COLUMN()),"") | C4: =IFERROR(INDEX(FILTER('전체API목록'!$A$2:$K$1200,'전체API목록'!$B$2:$B$1200="인증 및 세션"),ROW()-2,COLUMN()),"") | D4: =IFERROR(INDEX(FILTER('전체API목록'!$A$2:$K$1200,'전체API목록'!$B$2:$B$1200="인증 및 세션"),ROW()-2,COLUMN()),"") | E4: =IFERROR(INDEX(FILTER('전체API목록'!$A$2:$K$1200,'전체API목록'!$B$2:$B$1200="인증 및 세션"),ROW()-2,COLUMN()),"") | F4: =IFERROR(INDEX(FILTER('전체API목록'!$A$2:$K$1200,'전체API목록'!$B$2:$B$1200="인증 및 세션"),ROW()-2,COLUMN()),"") | G4: =IFERROR(INDEX(FILTER('전체API목록'!$A$2:$K$1200,'전체API목록'!$B$2:$B$1200="인증 및 세션"),ROW()-2,COLUMN()),"") | H4: =IFERROR(INDEX(FILTER('전체API목록'!$A$2:$K$1200,'전체API목록'!$B$2:$B$1200="인증 및 세션"),ROW()-2,COLUMN()),"") | ... K4: =IFERROR(INDEX(FILTER('전체API목록'!$A$2:$K$1200,'전체API목록'!$B$2:$B$1200="인증 및 세션"),ROW()-2,COLUMN()),"")
A5: =IFERROR(INDEX(FILTER('전체API목록'!$A$2:$K$1200,'전체API목록'!$B$2:$B$1200="인증 및 세션"),ROW()-2,COLUMN()),"") | B5: =IFERROR(INDEX(FILTER('전체API목록'!$A$2:$K$1200,'전체API목록'!$B$2:$B$1200="인증 및 세션"),ROW()-2,COLUMN()),"") | C5: =IFERROR(INDEX(FILTER('전체API목록'!$A$2:$K$1200,'전체API목록'!$B$2:$B$1200="인증 및 세션"),ROW()-2,COLUMN()),"") | D5: =IFERROR(INDEX(FILTER('전체API목록'!$A$2:$K$1200,'전체API목록'!$B$2:$B$1200="인증 및 세션"),ROW()-2,COLUMN()),"") | E5: =IFERROR(INDEX(FILTER('전체API목록'!$A$2:$K$1200,'전체API목록'!$B$2:$B$1200="인증 및 세션"),ROW()-2,COLUMN()),"") | F5: =IFERROR(INDEX(FILTER('전체API목록'!$A$2:$K$1200,'전체API목록'!$B$2:$B$1200="인증 및 세션"),ROW()-2,COLUMN()),"") | G5: =IFERROR(INDEX(FILTER('전체API목록'!$A$2:$K$1200,'전체API목록'!$B$2:$B$1200="인증 및 세션"),ROW()-2,COLUMN()),"") | H5: =IFERROR(INDEX(FILTER('전체API목록'!$A$2:$K$1200,'전체API목록'!$B$2:$B$1200="인증 및 세션"),ROW()-2,COLUMN()),"") | ... K5: =IFERROR(INDEX(FILTER('전체API목록'!$A$2:$K$1200,'전체API목록'!$B$2:$B$1200="인증 및 세션"),ROW()-2,COLUMN()),"")
A6: =IFERROR(INDEX(FILTER('전체API목록'!$A$2:$K$1200,'전체API목록'!$B$2:$B$1200="인증 및 세션"),ROW()-2,COLUMN()),"") | B6: =IFERROR(INDEX(FILTER('전체API목록'!$A$2:$K$1200,'전체API목록'!$B$2:$B$1200="인증 및 세션"),ROW()-2,COLUMN()),"") | C6: =IFERROR(INDEX(FILTER('전체API목록'!$A$2:$K$1200,'전체API목록'!$B$2:$B$1200="인증 및 세션"),ROW()-2,COLUMN()),"") | D6: =IFERROR(INDEX(FILTER('전체API목록'!$A$2:$K$1200,'전체API목록'!$B$2:$B$1200="인증 및 세션"),ROW()-2,COLUMN()),"") | E6: =IFERROR(INDEX(FILTER('전체API목록'!$A$2:$K$1200,'전체API목록'!$B$2:$B$1200="인증 및 세션"),ROW()-2,COLUMN()),"") | F6: =IFERROR(INDEX(FILTER('전체API목록'!$A$2:$K$1200,'전체API목록'!$B$2:$B$1200="인증 및 세션"),ROW()-2,COLUMN()),"") | G6: =IFERROR(INDEX(FILTER('전체API목록'!$A$2:$K$1200,'전체API목록'!$B$2:$B$1200="인증 및 세션"),ROW()-2,COLUMN()),"") | H6: =IFERROR(INDEX(FILTER('전체API목록'!$A$2:$K$1200,'전체API목록'!$B$2:$B$1200="인증 및 세션"),ROW()-2,COLUMN()),"") | ... K6: =IFERROR(INDEX(FILTER('전체API목록'!$A$2:$K$1200,'전체API목록'!$B$2:$B$1200="인증 및 세션"),ROW()-2,COLUMN()),"")
A7: =IFERROR(INDEX(FILTER('전체API목록'!$A$2:$K$1200,'전체API목록'!$B$2:$B$1200="인증 및 세션"),ROW()-2,COLUMN()),"") | B7: =IFERROR(INDEX(FILTER('전체API목록'!$A$2:$K$1200,'전체API목록'!$B$2:$B$1200="인증 및 세션"),ROW()-2,COLUMN()),"") | C7: =IFERROR(INDEX(FILTER('전체API목록'!$A$2:$K$1200,'전체API목록'!$B$2:$B$1200="인증 및 세션"),ROW()-2,COLUMN()),"") | D7: =IFERROR(INDEX(FILTER('전체API목록'!$A$2:$K$1200,'전체API목록'!$B$2:$B$1200="인증 및 세션"),ROW()-2,COLUMN()),"") | E7: =IFERROR(INDEX(FILTER('전체API목록'!$A$2:$K$1200,'전체API목록'!$B$2:$B$1200="인증 및 세션"),ROW()-2,COLUMN()),"") | F7: =IFERROR(INDEX(FILTER('전체API목록'!$A$2:$K$1200,'전체API목록'!$B$2:$B$1200="인증 및 세션"),ROW()-2,COLUMN()),"") | G7: =IFERROR(INDEX(FILTER('전체API목록'!$A$2:$K$1200,'전체API목록'!$B$2:$B$1200="인증 및 세션"),ROW()-2,COLUMN()),"") | H7: =IFERROR(INDEX(FILTER('전체API목록'!$A$2:$K$1200,'전체API목록'!$B$2:$B$1200="인증 및 세션"),ROW()-2,COLUMN()),"") | ... K7: =IFERROR(INDEX(FILTER('전체API목록'!$A$2:$K$1200,'전체API목록'!$B$2:$B$1200="인증 및 세션"),ROW()-2,COLUMN()),"")
A8: =IFERROR(INDEX(FILTER('전체API목록'!$A$2:$K$1200,'전체API목록'!$B$2:$B$1200="인증 및 세션"),ROW()-2,COLUMN()),"") | B8: =IFERROR(INDEX(FILTER('전체API목록'!$A$2:$K$1200,'전체API목록'!$B$2:$B$1200="인증 및 세션"),ROW()-2,COLUMN()),"") | C8: =IFERROR(INDEX(FILTER('전체API목록'!$A$2:$K$1200,'전체API목록'!$B$2:$B$1200="인증 및 세션"),ROW()-2,COLUMN()),"") | D8: =IFERROR(INDEX(FILTER('전체API목록'!$A$2:$K$1200,'전체API목록'!$B$2:$B$1200="인증 및 세션"),ROW()-2,COLUMN()),"") | E8: =IFERROR(INDEX(FILTER('전체API목록'!$A$2:$K$1200,'전체API목록'!$B$2:$B$1200="인증 및 세션"),ROW()-2,COLUMN()),"") | F8: =IFERROR(INDEX(FILTER('전체API목록'!$A$2:$K$1200,'전체API목록'!$B$2:$B$1200="인증 및 세션"),ROW()-2,COLUMN()),"") | G8: =IFERROR(INDEX(FILTER('전체API목록'!$A$2:$K$1200,'전체API목록'!$B$2:$B$1200="인증 및 세션"),ROW()-2,COLUMN()),"") | H8: =IFERROR(INDEX(FILTER('전체API목록'!$A$2:$K$1200,'전체API목록'!$B$2:$B$1200="인증 및 세션"),ROW()-2,COLUMN()),"") | ... K8: =IFERROR(INDEX(FILTER('전체API목록'!$A$2:$K$1200,'전체API목록'!$B$2:$B$1200="인증 및 세션"),ROW()-2,COLUMN()),"")
A9: =IFERROR(INDEX(FILTER('전체API목록'!$A$2:$K$1200,'전체API목록'!$B$2:$B$1200="인증 및 세션"),ROW()-2,COLUMN()),"") | B9: =IFERROR(INDEX(FILTER('전체API목록'!$A$2:$K$1200,'전체API목록'!$B$2:$B$1200="인증 및 세션"),ROW()-2,COLUMN()),"") | C9: =IFERROR(INDEX(FILTER('전체API목록'!$A$2:$K$1200,'전체API목록'!$B$2:$B$1200="인증 및 세션"),ROW()-2,COLUMN()),"") | D9: =IFERROR(INDEX(FILTER('전체API목록'!$A$2:$K$1200,'전체API목록'!$B$2:$B$1200="인증 및 세션"),ROW()-2,COLUMN()),"") | E9: =IFERROR(INDEX(FILTER('전체API목록'!$A$2:$K$1200,'전체API목록'!$B$2:$B$1200="인증 및 세션"),ROW()-2,COLUMN()),"") | F9: =IFERROR(INDEX(FILTER('전체API목록'!$A$2:$K$1200,'전체API목록'!$B$2:$B$1200="인증 및 세션"),ROW()-2,COLUMN()),"") | G9: =IFERROR(INDEX(FILTER('전체API목록'!$A$2:$K$1200,'전체API목록'!$B$2:$B$1200="인증 및 세션"),ROW()-2,COLUMN()),"") | H9: =IFERROR(INDEX(FILTER('전체API목록'!$A$2:$K$1200,'전체API목록'!$B$2:$B$1200="인증 및 세션"),ROW()-2,COLUMN()),"") | ... K9: =IFERROR(INDEX(FILTER('전체API목록'!$A$2:$K$1200,'전체API목록'!$B$2:$B$1200="인증 및 세션"),ROW()-2,COLUMN()),"")
A10: =IFERROR(INDEX(FILTER('전체API목록'!$A$2:$K$1200,'전체API목록'!$B$2:$B$1200="인증 및 세션"),ROW()-2,COLUMN()),"") | B10: =IFERROR(INDEX(FILTER('전체API목록'!$A$2:$K$1200,'전체API목록'!$B$2:$B$1200="인증 및 세션"),ROW()-2,COLUMN()),"") | C10: =IFERROR(INDEX(FILTER('전체API목록'!$A$2:$K$1200,'전체API목록'!$B$2:$B$1200="인증 및 세션"),ROW()-2,COLUMN()),"") | D10: =IFERROR(INDEX(FILTER('전체API목록'!$A$2:$K$1200,'전체API목록'!$B$2:$B$1200="인증 및 세션"),ROW()-2,COLUMN()),"") | E10: =IFERROR(INDEX(FILTER('전체API목록'!$A$2:$K$1200,'전체API목록'!$B$2:$B$1200="인증 및 세션"),ROW()-2,COLUMN()),"") | F10: =IFERROR(INDEX(FILTER('전체API목록'!$A$2:$K$1200,'전체API목록'!$B$2:$B$1200="인증 및 세션"),ROW()-2,COLUMN()),"") | G10: =IFERROR(INDEX(FILTER('전체API목록'!$A$2:$K$1200,'전체API목록'!$B$2:$B$1200="인증 및 세션"),ROW()-2,COLUMN()),"") | H10: =IFERROR(INDEX(FILTER('전체API목록'!$A$2:$K$1200,'전체API목록'!$B$2:$B$1200="인증 및 세션"),ROW()-2,COLUMN()),"") | ... K10: =IFERROR(INDEX(FILTER('전체API목록'!$A$2:$K$1200,'전체API목록'!$B$2:$B$1200="인증 및 세션"),ROW()-2,COLUMN()),"")
A11: =IFERROR(INDEX(FILTER('전체API목록'!$A$2:$K$1200,'전체API목록'!$B$2:$B$1200="인증 및 세션"),ROW()-2,COLUMN()),"") | B11: =IFERROR(INDEX(FILTER('전체API목록'!$A$2:$K$1200,'전체API목록'!$B$2:$B$1200="인증 및 세션"),ROW()-2,COLUMN()),"") | C11: =IFERROR(INDEX(FILTER('전체API목록'!$A$2:$K$1200,'전체API목록'!$B$2:$B$1200="인증 및 세션"),ROW()-2,COLUMN()),"") | D11: =IFERROR(INDEX(FILTER('전체API목록'!$A$2:$K$1200,'전체API목록'!$B$2:$B$1200="인증 및 세션"),ROW()-2,COLUMN()),"") | E11: =IFERROR(INDEX(FILTER('전체API목록'!$A$2:$K$1200,'전체API목록'!$B$2:$B$1200="인증 및 세션"),ROW()-2,COLUMN()),"") | F11: =IFERROR(INDEX(FILTER('전체API목록'!$A$2:$K$1200,'전체API목록'!$B$2:$B$1200="인증 및 세션"),ROW()-2,COLUMN()),"") | G11: =IFERROR(INDEX(FILTER('전체API목록'!$A$2:$K$1200,'전체API목록'!$B$2:$B$1200="인증 및 세션"),ROW()-2,COLUMN()),"") | H11: =IFERROR(INDEX(FILTER('전체API목록'!$A$2:$K$1200,'전체API목록'!$B$2:$B$1200="인증 및 세션"),ROW()-2,COLUMN()),"") | ... K11: =IFERROR(INDEX(FILTER('전체API목록'!$A$2:$K$1200,'전체API목록'!$B$2:$B$1200="인증 및 세션"),ROW()-2,COLUMN()),"")
A12: =IFERROR(INDEX(FILTER('전체API목록'!$A$2:$K$1200,'전체API목록'!$B$2:$B$1200="인증 및 세션"),ROW()-2,COLUMN()),"") | B12: =IFERROR(INDEX(FILTER('전체API목록'!$A$2:$K$1200,'전체API목록'!$B$2:$B$1200="인증 및 세션"),ROW()-2,COLUMN()),"") | C12: =IFERROR(INDEX(FILTER('전체API목록'!$A$2:$K$1200,'전체API목록'!$B$2:$B$1200="인증 및 세션"),ROW()-2,COLUMN()),"") | D12: =IFERROR(INDEX(FILTER('전체API목록'!$A$2:$K$1200,'전체API목록'!$B$2:$B$1200="인증 및 세션"),ROW()-2,COLUMN()),"") | E12: =IFERROR(INDEX(FILTER('전체API목록'!$A$2:$K$1200,'전체API목록'!$B$2:$B$1200="인증 및 세션"),ROW()-2,COLUMN()),"") | F12: =IFERROR(INDEX(FILTER('전체API목록'!$A$2:$K$1200,'전체API목록'!$B$2:$B$1200="인증 및 세션"),ROW()-2,COLUMN()),"") | G12: =IFERROR(INDEX(FILTER('전체API목록'!$A$2:$K$1200,'전체API목록'!$B$2:$B$1200="인증 및 세션"),ROW()-2,COLUMN()),"") | H12: =IFERROR(INDEX(FILTER('전체API목록'!$A$2:$K$1200,'전체API목록'!$B$2:$B$1200="인증 및 세션"),ROW()-2,COLUMN()),"") | ... K12: =IFERROR(INDEX(FILTER('전체API목록'!$A$2:$K$1200,'전체API목록'!$B$2:$B$1200="인증 및 세션"),ROW()-2,COLUMN()),"")
A13: =IFERROR(INDEX(FILTER('전체API목록'!$A$2:$K$1200,'전체API목록'!$B$2:$B$1200="인증 및 세션"),ROW()-2,COLUMN()),"") | B13: =IFERROR(INDEX(FILTER('전체API목록'!$A$2:$K$1200,'전체API목록'!$B$2:$B$1200="인증 및 세션"),ROW()-2,COLUMN()),"") | C13: =IFERROR(INDEX(FILTER('전체API목록'!$A$2:$K$1200,'전체API목록'!$B$2:$B$1200="인증 및 세션"),ROW()-2,COLUMN()),"") | D13: =IFERROR(INDEX(FILTER('전체API목록'!$A$2:$K$1200,'전체API목록'!$B$2:$B$1200="인증 및 세션"),ROW()-2,COLUMN()),"") | E13: =IFERROR(INDEX(FILTER('전체API목록'!$A$2:$K$1200,'전체API목록'!$B$2:$B$1200="인증 및 세션"),ROW()-2,COLUMN()),"") | F13: =IFERROR(INDEX(FILTER('전체API목록'!$A$2:$K$1200,'전체API목록'!$B$2:$B$1200="인증 및 세션"),ROW()-2,COLUMN()),"") | G13: =IFERROR(INDEX(FILTER('전체API목록'!$A$2:$K$1200,'전체API목록'!$B$2:$B$1200="인증 및 세션"),ROW()-2,COLUMN()),"") | H13: =IFERROR(INDEX(FILTER('전체API목록'!$A$2:$K$1200,'전체API목록'!$B$2:$B$1200="인증 및 세션"),ROW()-2,COLUMN()),"") | ... K13: =IFERROR(INDEX(FILTER('전체API목록'!$A$2:$K$1200,'전체API목록'!$B$2:$B$1200="인증 및 세션"),ROW()-2,COLUMN()),"")
A14: =IFERROR(INDEX(FILTER('전체API목록'!$A$2:$K$1200,'전체API목록'!$B$2:$B$1200="인증 및 세션"),ROW()-2,COLUMN()),"") | B14: =IFERROR(INDEX(FILTER('전체API목록'!$A$2:$K$1200,'전체API목록'!$B$2:$B$1200="인증 및 세션"),ROW()-2,COLUMN()),"") | C14: =IFERROR(INDEX(FILTER('전체API목록'!$A$2:$K$1200,'전체API목록'!$B$2:$B$1200="인증 및 세션"),ROW()-2,COLUMN()),"") | D14: =IFERROR(INDEX(FILTER('전체API목록'!$A$2:$K$1200,'전체API목록'!$B$2:$B$1200="인증 및 세션"),ROW()-2,COLUMN()),"") | E14: =IFERROR(INDEX(FILTER('전체API목록'!$A$2:$K$1200,'전체API목록'!$B$2:$B$1200="인증 및 세션"),ROW()-2,COLUMN()),"") | F14: =IFERROR(INDEX(FILTER('전체API목록'!$A$2:$K$1200,'전체API목록'!$B$2:$B$1200="인증 및 세션"),ROW()-2,COLUMN()),"") | G14: =IFERROR(INDEX(FILTER('전체API목록'!$A$2:$K$1200,'전체API목록'!$B$2:$B$1200="인증 및 세션"),ROW()-2,COLUMN()),"") | H14: =IFERROR(INDEX(FILTER('전체API목록'!$A$2:$K$1200,'전체API목록'!$B$2:$B$1200="인증 및 세션"),ROW()-2,COLUMN()),"") | ... K14: =IFERROR(INDEX(FILTER('전체API목록'!$A$2:$K$1200,'전체API목록'!$B$2:$B$1200="인증 및 세션"),ROW()-2,COLUMN()),"")
... A1200: =IFERROR(INDEX(FILTER('전체API목록'!$A$2:$K$1200,'전체API목록'!$B$2:$B$1200="인증 및 세션"),ROW()-2,COLUMN()),"") | B1200: =IFERROR(INDEX(FILTER('전체API목록'!$A$2:$K$1200,'전체API목록'!$B$2:$B$1200="인증 및 세션"),ROW()-2,COLUMN()),"") | C1200: =IFERROR(INDEX(FILTER('전체API목록'!$A$2:$K$1200,'전체API목록'!$B$2:$B$1200="인증 및 세션"),ROW()-2,COLUMN()),"") | D1200: =IFERROR(INDEX(FILTER('전체API목록'!$A$2:$K$1200,'전체API목록'!$B$2:$B$1200="인증 및 세션"),ROW()-2,COLUMN()),"") | E1200: =IFERROR(INDEX(FILTER('전체API목록'!$A$2:$K$1200,'전체API목록'!$B$2:$B$1200="인증 및 세션"),ROW()-2,COLUMN()),"") | F1200: =IFERROR(INDEX(FILTER('전체API목록'!$A$2:$K$1200,'전체API목록'!$B$2:$B$1200="인증 및 세션"),ROW()-2,COLUMN()),"") | G1200: =IFERROR(INDEX(FILTER('전체API목록'!$A$2:$K$1200,'전체API목록'!$B$2:$B$1200="인증 및 세션"),ROW()-2,COLUMN()),"") | H1200: =IFERROR(INDEX(FILTER('전체API목록'!$A$2:$K$1200,'전체API목록'!$B$2:$B$1200="인증 및 세션"),ROW()-2,COLUMN()),"") | ... K1200: =IFERROR(INDEX(FILTER('전체API목록'!$A$2:$K$1200,'전체API목록'!$B$2:$B$1200="인증 및 세션"),ROW()-2,COLUMN()),"")

Sheet 메시지 대화
A1: 메시지 대화 API 명세
A2: 번호 | B2: 카테고리 | C2: 프로그램ID | D2: API명 | E2: Method | F2: Endpoint | G2: 설명 | H2: Request | I2: Response | J2: 권한 | K2: 비고
A3: =IFERROR(INDEX(FILTER('전체API목록'!$A$2:$K$1200,'전체API목록'!$B$2:$B$1200="메시지 대화"),ROW()-2,COLUMN()),"") | B3: =IFERROR(INDEX(FILTER('전체API목록'!$A$2:$K$1200,'전체API목록'!$B$2:$B$1200="메시지 대화"),ROW()-2,COLUMN()),"") | C3: =IFERROR(INDEX(FILTER('전체API목록'!$A$2:$K$1200,'전체API목록'!$B$2:$B$1200="메시지 대화"),ROW()-2,COLUMN()),"") | D3: =IFERROR(INDEX(FILTER('전체API목록'!$A$2:$K$1200,'전체API목록'!$B$2:$B$1200="메시지 대화"),ROW()-2,COLUMN()),"") | E3: =IFERROR(INDEX(FILTER('전체API목록'!$A$2:$K$1200,'전체API목록'!$B$2:$B$1200="메시지 대화"),ROW()-2,COLUMN()),"") | F3: =IFERROR(INDEX(FILTER('전체API목록'!$A$2:$K$1200,'전체API목록'!$B$2:$B$1200="메시지 대화"),ROW()-2,COLUMN()),"") | G3: =IFERROR(INDEX(FILTER('전체API목록'!$A$2:$K$1200,'전체API목록'!$B$2:$B$1200="메시지 대화"),ROW()-2,COLUMN()),"") | H3: =IFERROR(INDEX(FILTER('전체API목록'!$A$2:$K$1200,'전체API목록'!$B$2:$B$1200="메시지 대화"),ROW()-2,COLUMN()),"") | ... K3: =IFERROR(INDEX(FILTER('전체API목록'!$A$2:$K$1200,'전체API목록'!$B$2:$B$1200="메시지 대화"),ROW()-2,COLUMN()),"")
A4: =IFERROR(INDEX(FILTER('전체API목록'!$A$2:$K$1200,'전체API목록'!$B$2:$B$1200="메시지 대화"),ROW()-2,COLUMN()),"") | B4: =IFERROR(INDEX(FILTER('전체API목록'!$A$2:$K$1200,'전체API목록'!$B$2:$B$1200="메시지 대화"),ROW()-2,COLUMN()),"") | C4: =IFERROR(INDEX(FILTER('전체API목록'!$A$2:$K$1200,'전체API목록'!$B$2:$B$1200="메시지 대화"),ROW()-2,COLUMN()),"") | D4: =IFERROR(INDEX(FILTER('전체API목록'!$A$2:$K$1200,'전체API목록'!$B$2:$B$1200="메시지 대화"),ROW()-2,COLUMN()),"") | E4: =IFERROR(INDEX(FILTER('전체API목록'!$A$2:$K$1200,'전체API목록'!$B$2:$B$1200="메시지 대화"),ROW()-2,COLUMN()),"") | F4: =IFERROR(INDEX(FILTER('전체API목록'!$A$2:$K$1200,'전체API목록'!$B$2:$B$1200="메시지 대화"),ROW()-2,COLUMN()),"") | G4: =IFERROR(INDEX(FILTER('전체API목록'!$A$2:$K$1200,'전체API목록'!$B$2:$B$1200="메시지 대화"),ROW()-2,COLUMN()),"") | H4: =IFERROR(INDEX(FILTER('전체API목록'!$A$2:$K$1200,'전체API목록'!$B$2:$B$1200="메시지 대화"),ROW()-2,COLUMN()),"") | ... K4: =IFERROR(INDEX(FILTER('전체API목록'!$A$2:$K$1200,'전체API목록'!$B$2:$B$1200="메시지 대화"),ROW()-2,COLUMN()),"")
A5: =IFERROR(INDEX(FILTER('전체API목록'!$A$2:$K$1200,'전체API목록'!$B$2:$B$1200="메시지 대화"),ROW()-2,COLUMN()),"") | B5: =IFERROR(INDEX(FILTER('전체API목록'!$A$2:$K$1200,'전체API목록'!$B$2:$B$1200="메시지 대화"),ROW()-2,COLUMN()),"") | C5: =IFERROR(INDEX(FILTER('전체API목록'!$A$2:$K$1200,'전체API목록'!$B$2:$B$1200="메시지 대화"),ROW()-2,COLUMN()),"") | D5: =IFERROR(INDEX(FILTER('전체API목록'!$A$2:$K$1200,'전체API목록'!$B$2:$B$1200="메시지 대화"),ROW()-2,COLUMN()),"") | E5: =IFERROR(INDEX(FILTER('전체API목록'!$A$2:$K$1200,'전체API목록'!$B$2:$B$1200="메시지 대화"),ROW()-2,COLUMN()),"") | F5: =IFERROR(INDEX(FILTER('전체API목록'!$A$2:$K$1200,'전체API목록'!$B$2:$B$1200="메시지 대화"),ROW()-2,COLUMN()),"") | G5: =IFERROR(INDEX(FILTER('전체API목록'!$A$2:$K$1200,'전체API목록'!$B$2:$B$1200="메시지 대화"),ROW()-2,COLUMN()),"") | H5: =IFERROR(INDEX(FILTER('전체API목록'!$A$2:$K$1200,'전체API목록'!$B$2:$B$1200="메시지 대화"),ROW()-2,COLUMN()),"") | ... K5: =IFERROR(INDEX(FILTER('전체API목록'!$A$2:$K$1200,'전체API목록'!$B$2:$B$1200="메시지 대화"),ROW()-2,COLUMN()),"")
A6: =IFERROR(INDEX(FILTER('전체API목록'!$A$2:$K$1200,'전체API목록'!$B$2:$B$1200="메시지 대화"),ROW()-2,COLUMN()),"") | B6: =IFERROR(INDEX(FILTER('전체API목록'!$A$2:$K$1200,'전체API목록'!$B$2:$B$1200="메시지 대화"),ROW()-2,COLUMN()),"") | C6: =IFERROR(INDEX(FILTER('전체API목록'!$A$2:$K$1200,'전체API목록'!$B$2:$B$1200="메시지 대화"),ROW()-2,COLUMN()),"") | D6: =IFERROR(INDEX(FILTER('전체API목록'!$A$2:$K$1200,'전체API목록'!$B$2:$B$1200="메시지 대화"),ROW()-2,COLUMN()),"") | E6: =IFERROR(INDEX(FILTER('전체API목록'!$A$2:$K$1200,'전체API목록'!$B$2:$B$1200="메시지 대화"),ROW()-2,COLUMN()),"") | F6: =IFERROR(INDEX(FILTER('전체API목록'!$A$2:$K$1200,'전체API목록'!$B$2:$B$1200="메시지 대화"),ROW()-2,COLUMN()),"") | G6: =IFERROR(INDEX(FILTER('전체API목록'!$A$2:$K$1200,'전체API목록'!$B$2:$B$1200="메시지 대화"),ROW()-2,COLUMN()),"") | H6: =IFERROR(INDEX(FILTER('전체API목록'!$A$2:$K$1200,'전체API목록'!$B$2:$B$1200="메시지 대화"),ROW()-2,COLUMN()),"") | ... K6: =IFERROR(INDEX(FILTER('전체API목록'!$A$2:$K$1200,'전체API목록'!$B$2:$B$1200="메시지 대화"),ROW()-2,COLUMN()),"")
A7: =IFERROR(INDEX(FILTER('전체API목록'!$A$2:$K$1200,'전체API목록'!$B$2:$B$1200="메시지 대화"),ROW()-2,COLUMN()),"") | B7: =IFERROR(INDEX(FILTER('전체API목록'!$A$2:$K$1200,'전체API목록'!$B$2:$B$1200="메시지 대화"),ROW()-2,COLUMN()),"") | C7: =IFERROR(INDEX(FILTER('전체API목록'!$A$2:$K$1200,'전체API목록'!$B$2:$B$1200="메시지 대화"),ROW()-2,COLUMN()),"") | D7: =IFERROR(INDEX(FILTER('전체API목록'!$A$2:$K$1200,'전체API목록'!$B$2:$B$1200="메시지 대화"),ROW()-2,COLUMN()),"") | E7: =IFERROR(INDEX(FILTER('전체API목록'!$A$2:$K$1200,'전체API목록'!$B$2:$B$1200="메시지 대화"),ROW()-2,COLUMN()),"") | F7: =IFERROR(INDEX(FILTER('전체API목록'!$A$2:$K$1200,'전체API목록'!$B$2:$B$1200="메시지 대화"),ROW()-2,COLUMN()),"") | G7: =IFERROR(INDEX(FILTER('전체API목록'!$A$2:$K$1200,'전체API목록'!$B$2:$B$1200="메시지 대화"),ROW()-2,COLUMN()),"") | H7: =IFERROR(INDEX(FILTER('전체API목록'!$A$2:$K$1200,'전체API목록'!$B$2:$B$1200="메시지 대화"),ROW()-2,COLUMN()),"") | ... K7: =IFERROR(INDEX(FILTER('전체API목록'!$A$2:$K$1200,'전체API목록'!$B$2:$B$1200="메시지 대화"),ROW()-2,COLUMN()),"")
A8: =IFERROR(INDEX(FILTER('전체API목록'!$A$2:$K$1200,'전체API목록'!$B$2:$B$1200="메시지 대화"),ROW()-2,COLUMN()),"") | B8: =IFERROR(INDEX(FILTER('전체API목록'!$A$2:$K$1200,'전체API목록'!$B$2:$B$1200="메시지 대화"),ROW()-2,COLUMN()),"") | C8: =IFERROR(INDEX(FILTER('전체API목록'!$A$2:$K$1200,'전체API목록'!$B$2:$B$1200="메시지 대화"),ROW()-2,COLUMN()),"") | D8: =IFERROR(INDEX(FILTER('전체API목록'!$A$2:$K$1200,'전체API목록'!$B$2:$B$1200="메시지 대화"),ROW()-2,COLUMN()),"") | E8: =IFERROR(INDEX(FILTER('전체API목록'!$A$2:$K$1200,'전체API목록'!$B$2:$B$1200="메시지 대화"),ROW()-2,COLUMN()),"") | F8: =IFERROR(INDEX(FILTER('전체API목록'!$A$2:$K$1200,'전체API목록'!$B$2:$B$1200="메시지 대화"),ROW()-2,COLUMN()),"") | G8: =IFERROR(INDEX(FILTER('전체API목록'!$A$2:$K$1200,'전체API목록'!$B$2:$B$1200="메시지 대화"),ROW()-2,COLUMN()),"") | H8: =IFERROR(INDEX(FILTER('전체API목록'!$A$2:$K$1200,'전체API목록'!$B$2:$B$1200="메시지 대화"),ROW()-2,COLUMN()),"") | ... K8: =IFERROR(INDEX(FILTER('전체API목록'!$A$2:$K$1200,'전체API목록'!$B$2:$B$1200="메시지 대화"),ROW()-2,COLUMN()),"")
A9: =IFERROR(INDEX(FILTER('전체API목록'!$A$2:$K$1200,'전체API목록'!$B$2:$B$1200="메시지 대화"),ROW()-2,COLUMN()),"") | B9: =IFERROR(INDEX(FILTER('전체API목록'!$A$2:$K$1200,'전체API목록'!$B$2:$B$1200="메시지 대화"),ROW()-2,COLUMN()),"") | C9: =IFERROR(INDEX(FILTER('전체API목록'!$A$2:$K$1200,'전체API목록'!$B$2:$B$1200="메시지 대화"),ROW()-2,COLUMN()),"") | D9: =IFERROR(INDEX(FILTER('전체API목록'!$A$2:$K$1200,'전체API목록'!$B$2:$B$1200="메시지 대화"),ROW()-2,COLUMN()),"") | E9: =IFERROR(INDEX(FILTER('전체API목록'!$A$2:$K$1200,'전체API목록'!$B$2:$B$1200="메시지 대화"),ROW()-2,COLUMN()),"") | F9: =IFERROR(INDEX(FILTER('전체API목록'!$A$2:$K$1200,'전체API목록'!$B$2:$B$1200="메시지 대화"),ROW()-2,COLUMN()),"") | G9: =IFERROR(INDEX(FILTER('전체API목록'!$A$2:$K$1200,'전체API목록'!$B$2:$B$1200="메시지 대화"),ROW()-2,COLUMN()),"") | H9: =IFERROR(INDEX(FILTER('전체API목록'!$A$2:$K$1200,'전체API목록'!$B$2:$B$1200="메시지 대화"),ROW()-2,COLUMN()),"") | ... K9: =IFERROR(INDEX(FILTER('전체API목록'!$A$2:$K$1200,'전체API목록'!$B$2:$B$1200="메시지 대화"),ROW()-2,COLUMN()),"")
A10: =IFERROR(INDEX(FILTER('전체API목록'!$A$2:$K$1200,'전체API목록'!$B$2:$B$1200="메시지 대화"),ROW()-2,COLUMN()),"") | B10: =IFERROR(INDEX(FILTER('전체API목록'!$A$2:$K$1200,'전체API목록'!$B$2:$B$1200="메시지 대화"),ROW()-2,COLUMN()),"") | C10: =IFERROR(INDEX(FILTER('전체API목록'!$A$2:$K$1200,'전체API목록'!$B$2:$B$1200="메시지 대화"),ROW()-2,COLUMN()),"") | D10: =IFERROR(INDEX(FILTER('전체API목록'!$A$2:$K$1200,'전체API목록'!$B$2:$B$1200="메시지 대화"),ROW()-2,COLUMN()),"") | E10: =IFERROR(INDEX(FILTER('전체API목록'!$A$2:$K$1200,'전체API목록'!$B$2:$B$1200="메시지 대화"),ROW()-2,COLUMN()),"") | F10: =IFERROR(INDEX(FILTER('전체API목록'!$A$2:$K$1200,'전체API목록'!$B$2:$B$1200="메시지 대화"),ROW()-2,COLUMN()),"") | G10: =IFERROR(INDEX(FILTER('전체API목록'!$A$2:$K$1200,'전체API목록'!$B$2:$B$1200="메시지 대화"),ROW()-2,COLUMN()),"") | H10: =IFERROR(INDEX(FILTER('전체API목록'!$A$2:$K$1200,'전체API목록'!$B$2:$B$1200="메시지 대화"),ROW()-2,COLUMN()),"") | ... K10: =IFERROR(INDEX(FILTER('전체API목록'!$A$2:$K$1200,'전체API목록'!$B$2:$B$1200="메시지 대화"),ROW()-2,COLUMN()),"")
A11: =IFERROR(INDEX(FILTER('전체API목록'!$A$2:$K$1200,'전체API목록'!$B$2:$B$1200="메시지 대화"),ROW()-2,COLUMN()),"") | B11: =IFERROR(INDEX(FILTER('전체API목록'!$A$2:$K$1200,'전체API목록'!$B$2:$B$1200="메시지 대화"),ROW()-2,COLUMN()),"") | C11: =IFERROR(INDEX(FILTER('전체API목록'!$A$2:$K$1200,'전체API목록'!$B$2:$B$1200="메시지 대화"),ROW()-2,COLUMN()),"") | D11: =IFERROR(INDEX(FILTER('전체API목록'!$A$2:$K$1200,'전체API목록'!$B$2:$B$1200="메시지 대화"),ROW()-2,COLUMN()),"") | E11: =IFERROR(INDEX(FILTER('전체API목록'!$A$2:$K$1200,'전체API목록'!$B$2:$B$1200="메시지 대화"),ROW()-2,COLUMN()),"") | F11: =IFERROR(INDEX(FILTER('전체API목록'!$A$2:$K$1200,'전체API목록'!$B$2:$B$1200="메시지 대화"),ROW()-2,COLUMN()),"") | G11: =IFERROR(INDEX(FILTER('전체API목록'!$A$2:$K$1200,'전체API목록'!$B$2:$B$1200="메시지 대화"),ROW()-2,COLUMN()),"") | H11: =IFERROR(INDEX(FILTER('전체API목록'!$A$2:$K$1200,'전체API목록'!$B$2:$B$1200="메시지 대화"),ROW()-2,COLUMN()),"") | ... K11: =IFERROR(INDEX(FILTER('전체API목록'!$A$2:$K$1200,'전체API목록'!$B$2:$B$1200="메시지 대화"),ROW()-2,COLUMN()),"")
A12: =IFERROR(INDEX(FILTER('전체API목록'!$A$2:$K$1200,'전체API목록'!$B$2:$B$1200="메시지 대화"),ROW()-2,COLUMN()),"") | B12: =IFERROR(INDEX(FILTER('전체API목록'!$A$2:$K$1200,'전체API목록'!$B$2:$B$1200="메시지 대화"),ROW()-2,COLUMN()),"") | C12: =IFERROR(INDEX(FILTER('전체API목록'!$A$2:$K$1200,'전체API목록'!$B$2:$B$1200="메시지 대화"),ROW()-2,COLUMN()),"") | D12: =IFERROR(INDEX(FILTER('전체API목록'!$A$2:$K$1200,'전체API목록'!$B$2:$B$1200="메시지 대화"),ROW()-2,COLUMN()),"") | E12: =IFERROR(INDEX(FILTER('전체API목록'!$A$2:$K$1200,'전체API목록'!$B$2:$B$1200="메시지 대화"),ROW()-2,COLUMN()),"") | F12: =IFERROR(INDEX(FILTER('전체API목록'!$A$2:$K$1200,'전체API목록'!$B$2:$B$1200="메시지 대화"),ROW()-2,COLUMN()),"") | G12: =IFERROR(INDEX(FILTER('전체API목록'!$A$2:$K$1200,'전체API목록'!$B$2:$B$1200="메시지 대화"),ROW()-2,COLUMN()),"") | H12: =IFERROR(INDEX(FILTER('전체API목록'!$A$2:$K$1200,'전체API목록'!$B$2:$B$1200="메시지 대화"),ROW()-2,COLUMN()),"") | ... K12: =IFERROR(INDEX(FILTER('전체API목록'!$A$2:$K$1200,'전체API목록'!$B$2:$B$1200="메시지 대화"),ROW()-2,COLUMN()),"")
A13: =IFERROR(INDEX(FILTER('전체API목록'!$A$2:$K$1200,'전체API목록'!$B$2:$B$1200="메시지 대화"),ROW()-2,COLUMN()),"") | B13: =IFERROR(INDEX(FILTER('전체API목록'!$A$2:$K$1200,'전체API목록'!$B$2:$B$1200="메시지 대화"),ROW()-2,COLUMN()),"") | C13: =IFERROR(INDEX(FILTER('전체API목록'!$A$2:$K$1200,'전체API목록'!$B$2:$B$1200="메시지 대화"),ROW()-2,COLUMN()),"") | D13: =IFERROR(INDEX(FILTER('전체API목록'!$A$2:$K$1200,'전체API목록'!$B$2:$B$1200="메시지 대화"),ROW()-2,COLUMN()),"") | E13: =IFERROR(INDEX(FILTER('전체API목록'!$A$2:$K$1200,'전체API목록'!$B$2:$B$1200="메시지 대화"),ROW()-2,COLUMN()),"") | F13: =IFERROR(INDEX(FILTER('전체API목록'!$A$2:$K$1200,'전체API목록'!$B$2:$B$1200="메시지 대화"),ROW()-2,COLUMN()),"") | G13: =IFERROR(INDEX(FILTER('전체API목록'!$A$2:$K$1200,'전체API목록'!$B$2:$B$1200="메시지 대화"),ROW()-2,COLUMN()),"") | H13: =IFERROR(INDEX(FILTER('전체API목록'!$A$2:$K$1200,'전체API목록'!$B$2:$B$1200="메시지 대화"),ROW()-2,COLUMN()),"") | ... K13: =IFERROR(INDEX(FILTER('전체API목록'!$A$2:$K$1200,'전체API목록'!$B$2:$B$1200="메시지 대화"),ROW()-2,COLUMN()),"")
A14: =IFERROR(INDEX(FILTER('전체API목록'!$A$2:$K$1200,'전체API목록'!$B$2:$B$1200="메시지 대화"),ROW()-2,COLUMN()),"") | B14: =IFERROR(INDEX(FILTER('전체API목록'!$A$2:$K$1200,'전체API목록'!$B$2:$B$1200="메시지 대화"),ROW()-2,COLUMN()),"") | C14: =IFERROR(INDEX(FILTER('전체API목록'!$A$2:$K$1200,'전체API목록'!$B$2:$B$1200="메시지 대화"),ROW()-2,COLUMN()),"") | D14: =IFERROR(INDEX(FILTER('전체API목록'!$A$2:$K$1200,'전체API목록'!$B$2:$B$1200="메시지 대화"),ROW()-2,COLUMN()),"") | E14: =IFERROR(INDEX(FILTER('전체API목록'!$A$2:$K$1200,'전체API목록'!$B$2:$B$1200="메시지 대화"),ROW()-2,COLUMN()),"") | F14: =IFERROR(INDEX(FILTER('전체API목록'!$A$2:$K$1200,'전체API목록'!$B$2:$B$1200="메시지 대화"),ROW()-2,COLUMN()),"") | G14: =IFERROR(INDEX(FILTER('전체API목록'!$A$2:$K$1200,'전체API목록'!$B$2:$B$1200="메시지 대화"),ROW()-2,COLUMN()),"") | H14: =IFERROR(INDEX(FILTER('전체API목록'!$A$2:$K$1200,'전체API목록'!$B$2:$B$1200="메시지 대화"),ROW()-2,COLUMN()),"") | ... K14: =IFERROR(INDEX(FILTER('전체API목록'!$A$2:$K$1200,'전체API목록'!$B$2:$B$1200="메시지 대화"),ROW()-2,COLUMN()),"")
... A1200: =IFERROR(INDEX(FILTER('전체API목록'!$A$2:$K$1200,'전체API목록'!$B$2:$B$1200="메시지 대화"),ROW()-2,COLUMN()),"") | B1200: =IFERROR(INDEX(FILTER('전체API목록'!$A$2:$K$1200,'전체API목록'!$B$2:$B$1200="메시지 대화"),ROW()-2,COLUMN()),"") | C1200: =IFERROR(INDEX(FILTER('전체API목록'!$A$2:$K$1200,'전체API목록'!$B$2:$B$1200="메시지 대화"),ROW()-2,COLUMN()),"") | D1200: =IFERROR(INDEX(FILTER('전체API목록'!$A$2:$K$1200,'전체API목록'!$B$2:$B$1200="메시지 대화"),ROW()-2,COLUMN()),"") | E1200: =IFERROR(INDEX(FILTER('전체API목록'!$A$2:$K$1200,'전체API목록'!$B$2:$B$1200="메시지 대화"),ROW()-2,COLUMN()),"") | F1200: =IFERROR(INDEX(FILTER('전체API목록'!$A$2:$K$1200,'전체API목록'!$B$2:$B$1200="메시지 대화"),ROW()-2,COLUMN()),"") | G1200: =IFERROR(INDEX(FILTER('전체API목록'!$A$2:$K$1200,'전체API목록'!$B$2:$B$1200="메시지 대화"),ROW()-2,COLUMN()),"") | H1200: =IFERROR(INDEX(FILTER('전체API목록'!$A$2:$K$1200,'전체API목록'!$B$2:$B$1200="메시지 대화"),ROW()-2,COLUMN()),"") | ... K1200: =IFERROR(INDEX(FILTER('전체API목록'!$A$2:$K$1200,'전체API목록'!$B$2:$B$1200="메시지 대화"),ROW()-2,COLUMN()),"")

Sheet 스트리밍 SSE
A1: 스트리밍 SSE API 명세
A2: 번호 | B2: 카테고리 | C2: 프로그램ID | D2: API명 | E2: Method | F2: Endpoint | G2: 설명 | H2: Request | I2: Response | J2: 권한 | K2: 비고
A3: =IFERROR(INDEX(FILTER('전체API목록'!$A$2:$K$1200,'전체API목록'!$B$2:$B$1200="스트리밍 SSE"),ROW()-2,COLUMN()),"") | B3: =IFERROR(INDEX(FILTER('전체API목록'!$A$2:$K$1200,'전체API목록'!$B$2:$B$1200="스트리밍 SSE"),ROW()-2,COLUMN()),"") | C3: =IFERROR(INDEX(FILTER('전체API목록'!$A$2:$K$1200,'전체API목록'!$B$2:$B$1200="스트리밍 SSE"),ROW()-2,COLUMN()),"") | D3: =IFERROR(INDEX(FILTER('전체API목록'!$A$2:$K$1200,'전체API목록'!$B$2:$B$1200="스트리밍 SSE"),ROW()-2,COLUMN()),"") | E3: =IFERROR(INDEX(FILTER('전체API목록'!$A$2:$K$1200,'전체API목록'!$B$2:$B$1200="스트리밍 SSE"),ROW()-2,COLUMN()),"") | F3: =IFERROR(INDEX(FILTER('전체API목록'!$A$2:$K$1200,'전체API목록'!$B$2:$B$1200="스트리밍 SSE"),ROW()-2,COLUMN()),"") | G3: =IFERROR(INDEX(FILTER('전체API목록'!$A$2:$K$1200,'전체API목록'!$B$2:$B$1200="스트리밍 SSE"),ROW()-2,COLUMN()),"") | H3: =IFERROR(INDEX(FILTER('전체API목록'!$A$2:$K$1200,'전체API목록'!$B$2:$B$1200="스트리밍 SSE"),ROW()-2,COLUMN()),"") | ... K3: =IFERROR(INDEX(FILTER('전체API목록'!$A$2:$K$1200,'전체API목록'!$B$2:$B$1200="스트리밍 SSE"),ROW()-2,COLUMN()),"")
A4: =IFERROR(INDEX(FILTER('전체API목록'!$A$2:$K$1200,'전체API목록'!$B$2:$B$1200="스트리밍 SSE"),ROW()-2,COLUMN()),"") | B4: =IFERROR(INDEX(FILTER('전체API목록'!$A$2:$K$1200,'전체API목록'!$B$2:$B$1200="스트리밍 SSE"),ROW()-2,COLUMN()),"") | C4: =IFERROR(INDEX(FILTER('전체API목록'!$A$2:$K$1200,'전체API목록'!$B$2:$B$1200="스트리밍 SSE"),ROW()-2,COLUMN()),"") | D4: =IFERROR(INDEX(FILTER('전체API목록'!$A$2:$K$1200,'전체API목록'!$B$2:$B$1200="스트리밍 SSE"),ROW()-2,COLUMN()),"") | E4: =IFERROR(INDEX(FILTER('전체API목록'!$A$2:$K$1200,'전체API목록'!$B$2:$B$1200="스트리밍 SSE"),ROW()-2,COLUMN()),"") | F4: =IFERROR(INDEX(FILTER('전체API목록'!$A$2:$K$1200,'전체API목록'!$B$2:$B$1200="스트리밍 SSE"),ROW()-2,COLUMN()),"") | G4: =IFERROR(INDEX(FILTER('전체API목록'!$A$2:$K$1200,'전체API목록'!$B$2:$B$1200="스트리밍 SSE"),ROW()-2,COLUMN()),"") | H4: =IFERROR(INDEX(FILTER('전체API목록'!$A$2:$K$1200,'전체API목록'!$B$2:$B$1200="스트리밍 SSE"),ROW()-2,COLUMN()),"") | ... K4: =IFERROR(INDEX(FILTER('전체API목록'!$A$2:$K$1200,'전체API목록'!$B$2:$B$1200="스트리밍 SSE"),ROW()-2,COLUMN()),"")
A5: =IFERROR(INDEX(FILTER('전체API목록'!$A$2:$K$1200,'전체API목록'!$B$2:$B$1200="스트리밍 SSE"),ROW()-2,COLUMN()),"") | B5: =IFERROR(INDEX(FILTER('전체API목록'!$A$2:$K$1200,'전체API목록'!$B$2:$B$1200="스트리밍 SSE"),ROW()-2,COLUMN()),"") | C5: =IFERROR(INDEX(FILTER('전체API목록'!$A$2:$K$1200,'전체API목록'!$B$2:$B$1200="스트리밍 SSE"),ROW()-2,COLUMN()),"") | D5: =IFERROR(INDEX(FILTER('전체API목록'!$A$2:$K$1200,'전체API목록'!$B$2:$B$1200="스트리밍 SSE"),ROW()-2,COLUMN()),"") | E5: =IFERROR(INDEX(FILTER('전체API목록'!$A$2:$K$1200,'전체API목록'!$B$2:$B$1200="스트리밍 SSE"),ROW()-2,COLUMN()),"") | F5: =IFERROR(INDEX(FILTER('전체API목록'!$A$2:$K$1200,'전체API목록'!$B$2:$B$1200="스트리밍 SSE"),ROW()-2,COLUMN()),"") | G5: =IFERROR(INDEX(FILTER('전체API목록'!$A$2:$K$1200,'전체API목록'!$B$2:$B$1200="스트리밍 SSE"),ROW()-2,COLUMN()),"") | H5: =IFERROR(INDEX(FILTER('전체API목록'!$A$2:$K$1200,'전체API목록'!$B$2:$B$1200="스트리밍 SSE"),ROW()-2,COLUMN()),"") | ... K5: =IFERROR(INDEX(FILTER('전체API목록'!$A$2:$K$1200,'전체API목록'!$B$2:$B$1200="스트리밍 SSE"),ROW()-2,COLUMN()),"")
A6: =IFERROR(INDEX(FILTER('전체API목록'!$A$2:$K$1200,'전체API목록'!$B$2:$B$1200="스트리밍 SSE"),ROW()-2,COLUMN()),"") | B6: =IFERROR(INDEX(FILTER('전체API목록'!$A$2:$K$1200,'전체API목록'!$B$2:$B$1200="스트리밍 SSE"),ROW()-2,COLUMN()),"") | C6: =IFERROR(INDEX(FILTER('전체API목록'!$A$2:$K$1200,'전체API목록'!$B$2:$B$1200="스트리밍 SSE"),ROW()-2,COLUMN()),"") | D6: =IFERROR(INDEX(FILTER('전체API목록'!$A$2:$K$1200,'전체API목록'!$B$2:$B$1200="스트리밍 SSE"),ROW()-2,COLUMN()),"") | E6: =IFERROR(INDEX(FILTER('전체API목록'!$A$2:$K$1200,'전체API목록'!$B$2:$B$1200="스트리밍 SSE"),ROW()-2,COLUMN()),"") | F6: =IFERROR(INDEX(FILTER('전체API목록'!$A$2:$K$1200,'전체API목록'!$B$2:$B$1200="스트리밍 SSE"),ROW()-2,COLUMN()),"") | G6: =IFERROR(INDEX(FILTER('전체API목록'!$A$2:$K$1200,'전체API목록'!$B$2:$B$1200="스트리밍 SSE"),ROW()-2,COLUMN()),"") | H6: =IFERROR(INDEX(FILTER('전체API목록'!$A$2:$K$1200,'전체API목록'!$B$2:$B$1200="스트리밍 SSE"),ROW()-2,COLUMN()),"") | ... K6: =IFERROR(INDEX(FILTER('전체API목록'!$A$2:$K$1200,'전체API목록'!$B$2:$B$1200="스트리밍 SSE"),ROW()-2,COLUMN()),"")
A7: =IFERROR(INDEX(FILTER('전체API목록'!$A$2:$K$1200,'전체API목록'!$B$2:$B$1200="스트리밍 SSE"),ROW()-2,COLUMN()),"") | B7: =IFERROR(INDEX(FILTER('전체API목록'!$A$2:$K$1200,'전체API목록'!$B$2:$B$1200="스트리밍 SSE"),ROW()-2,COLUMN()),"") | C7: =IFERROR(INDEX(FILTER('전체API목록'!$A$2:$K$1200,'전체API목록'!$B$2:$B$1200="스트리밍 SSE"),ROW()-2,COLUMN()),"") | D7: =IFERROR(INDEX(FILTER('전체API목록'!$A$2:$K$1200,'전체API목록'!$B$2:$B$1200="스트리밍 SSE"),ROW()-2,COLUMN()),"") | E7: =IFERROR(INDEX(FILTER('전체API목록'!$A$2:$K$1200,'전체API목록'!$B$2:$B$1200="스트리밍 SSE"),ROW()-2,COLUMN()),"") | F7: =IFERROR(INDEX(FILTER('전체API목록'!$A$2:$K$1200,'전체API목록'!$B$2:$B$1200="스트리밍 SSE"),ROW()-2,COLUMN()),"") | G7: =IFERROR(INDEX(FILTER('전체API목록'!$A$2:$K$1200,'전체API목록'!$B$2:$B$1200="스트리밍 SSE"),ROW()-2,COLUMN()),"") | H7: =IFERROR(INDEX(FILTER('전체API목록'!$A$2:$K$1200,'전체API목록'!$B$2:$B$1200="스트리밍 SSE"),ROW()-2,COLUMN()),"") | ... K7: =IFERROR(INDEX(FILTER('전체API목록'!$A$2:$K$1200,'전체API목록'!$B$2:$B$1200="스트리밍 SSE"),ROW()-2,COLUMN()),"")
A8: =IFERROR(INDEX(FILTER('전체API목록'!$A$2:$K$1200,'전체API목록'!$B$2:$B$1200="스트리밍 SSE"),ROW()-2,COLUMN()),"") | B8: =IFERROR(INDEX(FILTER('전체API목록'!$A$2:$K$1200,'전체API목록'!$B$2:$B$1200="스트리밍 SSE"),ROW()-2,COLUMN()),"") | C8: =IFERROR(INDEX(FILTER('전체API목록'!$A$2:$K$1200,'전체API목록'!$B$2:$B$1200="스트리밍 SSE"),ROW()-2,COLUMN()),"") | D8: =IFERROR(INDEX(FILTER('전체API목록'!$A$2:$K$1200,'전체API목록'!$B$2:$B$1200="스트리밍 SSE"),ROW()-2,COLUMN()),"") | E8: =IFERROR(INDEX(FILTER('전체API목록'!$A$2:$K$1200,'전체API목록'!$B$2:$B$1200="스트리밍 SSE"),ROW()-2,COLUMN()),"") | F8: =IFERROR(INDEX(FILTER('전체API목록'!$A$2:$K$1200,'전체API목록'!$B$2:$B$1200="스트리밍 SSE"),ROW()-2,COLUMN()),"") | G8: =IFERROR(INDEX(FILTER('전체API목록'!$A$2:$K$1200,'전체API목록'!$B$2:$B$1200="스트리밍 SSE"),ROW()-2,COLUMN()),"") | H8: =IFERROR(INDEX(FILTER('전체API목록'!$A$2:$K$1200,'전체API목록'!$B$2:$B$1200="스트리밍 SSE"),ROW()-2,COLUMN()),"") | ... K8: =IFERROR(INDEX(FILTER('전체API목록'!$A$2:$K$1200,'전체API목록'!$B$2:$B$1200="스트리밍 SSE"),ROW()-2,COLUMN()),"")
A9: =IFERROR(INDEX(FILTER('전체API목록'!$A$2:$K$1200,'전체API목록'!$B$2:$B$1200="스트리밍 SSE"),ROW()-2,COLUMN()),"") | B9: =IFERROR(INDEX(FILTER('전체API목록'!$A$2:$K$1200,'전체API목록'!$B$2:$B$1200="스트리밍 SSE"),ROW()-2,COLUMN()),"") | C9: =IFERROR(INDEX(FILTER('전체API목록'!$A$2:$K$1200,'전체API목록'!$B$2:$B$1200="스트리밍 SSE"),ROW()-2,COLUMN()),"") | D9: =IFERROR(INDEX(FILTER('전체API목록'!$A$2:$K$1200,'전체API목록'!$B$2:$B$1200="스트리밍 SSE"),ROW()-2,COLUMN()),"") | E9: =IFERROR(INDEX(FILTER('전체API목록'!$A$2:$K$1200,'전체API목록'!$B$2:$B$1200="스트리밍 SSE"),ROW()-2,COLUMN()),"") | F9: =IFERROR(INDEX(FILTER('전체API목록'!$A$2:$K$1200,'전체API목록'!$B$2:$B$1200="스트리밍 SSE"),ROW()-2,COLUMN()),"") | G9: =IFERROR(INDEX(FILTER('전체API목록'!$A$2:$K$1200,'전체API목록'!$B$2:$B$1200="스트리밍 SSE"),ROW()-2,COLUMN()),"") | H9: =IFERROR(INDEX(FILTER('전체API목록'!$A$2:$K$1200,'전체API목록'!$B$2:$B$1200="스트리밍 SSE"),ROW()-2,COLUMN()),"") | ... K9: =IFERROR(INDEX(FILTER('전체API목록'!$A$2:$K$1200,'전체API목록'!$B$2:$B$1200="스트리밍 SSE"),ROW()-2,COLUMN()),"")
A10: =IFERROR(INDEX(FILTER('전체API목록'!$A$2:$K$1200,'전체API목록'!$B$2:$B$1200="스트리밍 SSE"),ROW()-2,COLUMN()),"") | B10: =IFERROR(INDEX(FILTER('전체API목록'!$A$2:$K$1200,'전체API목록'!$B$2:$B$1200="스트리밍 SSE"),ROW()-2,COLUMN()),"") | C10: =IFERROR(INDEX(FILTER('전체API목록'!$A$2:$K$1200,'전체API목록'!$B$2:$B$1200="스트리밍 SSE"),ROW()-2,COLUMN()),"") | D10: =IFERROR(INDEX(FILTER('전체API목록'!$A$2:$K$1200,'전체API목록'!$B$2:$B$1200="스트리밍 SSE"),ROW()-2,COLUMN()),"") | E10: =IFERROR(INDEX(FILTER('전체API목록'!$A$2:$K$1200,'전체API목록'!$B$2:$B$1200="스트리밍 SSE"),ROW()-2,COLUMN()),"") | F10: =IFERROR(INDEX(FILTER('전체API목록'!$A$2:$K$1200,'전체API목록'!$B$2:$B$1200="스트리밍 SSE"),ROW()-2,COLUMN()),"") | G10: =IFERROR(INDEX(FILTER('전체API목록'!$A$2:$K$1200,'전체API목록'!$B$2:$B$1200="스트리밍 SSE"),ROW()-2,COLUMN()),"") | H10: =IFERROR(INDEX(FILTER('전체API목록'!$A$2:$K$1200,'전체API목록'!$B$2:$B$1200="스트리밍 SSE"),ROW()-2,COLUMN()),"") | ... K10: =IFERROR(INDEX(FILTER('전체API목록'!$A$2:$K$1200,'전체API목록'!$B$2:$B$1200="스트리밍 SSE"),ROW()-2,COLUMN()),"")
A11: =IFERROR(INDEX(FILTER('전체API목록'!$A$2:$K$1200,'전체API목록'!$B$2:$B$1200="스트리밍 SSE"),ROW()-2,COLUMN()),"") | B11: =IFERROR(INDEX(FILTER('전체API목록'!$A$2:$K$1200,'전체API목록'!$B$2:$B$1200="스트리밍 SSE"),ROW()-2,COLUMN()),"") | C11: =IFERROR(INDEX(FILTER('전체API목록'!$A$2:$K$1200,'전체API목록'!$B$2:$B$1200="스트리밍 SSE"),ROW()-2,COLUMN()),"") | D11: =IFERROR(INDEX(FILTER('전체API목록'!$A$2:$K$1200,'전체API목록'!$B$2:$B$1200="스트리밍 SSE"),ROW()-2,COLUMN()),"") | E11: =IFERROR(INDEX(FILTER('전체API목록'!$A$2:$K$1200,'전체API목록'!$B$2:$B$1200="스트리밍 SSE"),ROW()-2,COLUMN()),"") | F11: =IFERROR(INDEX(FILTER('전체API목록'!$A$2:$K$1200,'전체API목록'!$B$2:$B$1200="스트리밍 SSE"),ROW()-2,COLUMN()),"") | G11: =IFERROR(INDEX(FILTER('전체API목록'!$A$2:$K$1200,'전체API목록'!$B$2:$B$1200="스트리밍 SSE"),ROW()-2,COLUMN()),"") | H11: =IFERROR(INDEX(FILTER('전체API목록'!$A$2:$K$1200,'전체API목록'!$B$2:$B$1200="스트리밍 SSE"),ROW()-2,COLUMN()),"") | ... K11: =IFERROR(INDEX(FILTER('전체API목록'!$A$2:$K$1200,'전체API목록'!$B$2:$B$1200="스트리밍 SSE"),ROW()-2,COLUMN()),"")
